Workbook

Sheet INDEX & CONTROL PANEL
A1: AUTOMATED AHU SAVINGS REPORT INDEX
A2: Control Panel & Direct Navigation Links to Executive Dashboards and Monthly Reports
A4: REPORT NAVIGATION INDEX
A5: S.No | B5: Sheet / Module Name | C5: Description | D5: Direct Link to Sheet
A6: 1 | B6: Executive Dashboard | C6: High-level KPI Cards & Monthly Comparison Summary | D6: Go to Executive Dashboard Sheet >>
A7: 2 | B7: May 2026 | C7: Detailed daily tracker and savings analysis for May 2026 | D7: Go to May 2026 Sheet >>
A8: 3 | B8: June 2026 | C8: Detailed daily tracker and savings analysis for June 2026 | D8: Go to June 2026 Sheet >>
A9: 4 | B9: July 2026 | C9: Detailed daily tracker and savings analysis for July 2026 | D9: Go to July 2026 Sheet >>
A10: 5 | B10: August 2026 | C10: Detailed daily tracker and savings analysis for August 2026 | D10: Go to August 2026 Sheet >>
A15: SINGLE-FILE ZERO-EFFORT AUTOMATION INSTRUCTIONS
A17: 1. Open 'Daily AHU ON Off Time.xlsx' and enter/update ONLY: ON Time, OFF Time, and Current/Previous Readings (Difference).
A18: 2. Double-click the 'RUN_AUTO_UPDATE.bat' script in this folder whenever you finish updating the file.
A19: 3. The script automatically detects all months, adds new sheets, recalculates hourly costs, and rebuilds the Executive Dashboard instantly!
A20: 4. No other files needed! Energy tracker file is NOT required.

Sheet Executive Dashboard
A1: MONTH-WISE AHU SAVED HOURS & KWH COST DASHBOARD
A2: Executive Summary of Scheduled AHU Hours vs Actual Running Hours, Savings & KWH Consumption Costs
A4: TOTAL SCHEDULED AHU HOURS | D4: TOTAL ACTUAL RUN HOURS | G4: TOTAL SAVED SHUT-OFF HRS | J4: TOTAL KWH ENERGY COST | M4: TOTAL COST SAVED (RS)
A5: =C15 | D5: =D15 | G5: =I15 | J5: =K15 | M5: =N15
A9: SCHEDULED VS ACTUAL RUNNING HOURS & FINANCIAL SAVINGS BREAKDOWN
A10: Month | B10: Days | C10: Tot Sched AHU Hrs | D10: Tot Actual Run Hrs | E10: AHU-1 Saved (Hrs) | F10: AHU-2 Saved (Hrs) | G10: AHU-3 Saved (Hrs) | H10: AHU-4 Saved (Hrs) | I10: Total Saved Hrs | J10: KWH Consumption | K10: KWH Cost (Rs) | L10: Tot Actual Cost (Rs) | M10: Full Cost 8PM (Rs) | N10: Total Cost Saved (Rs)
A11: May 2026 | B11: 31 | C11: ='May 2026'!AQ38 | D11: ='May 2026'!AR38 | E11: ='May 2026'!G38 | F11: ='May 2026'!Q38 | G11: ='May 2026'!AA38 | H11: ='May 2026'!AK38 | I11: ='May 2026'!AS38 | J11: ='May 2026'!AT38 | K11: ='May 2026'!AU38 | L11: ='May 2026'!AV38 | M11: ='May 2026'!AW38 | N11: ='May 2026'!AX38
A12: June 2026 | B12: 30 | C12: ='June 2026'!AQ37 | D12: ='June 2026'!AR37 | E12: ='June 2026'!G37 | F12: ='June 2026'!Q37 | G12: ='June 2026'!AA37 | H12: ='June 2026'!AK37 | I12: ='June 2026'!AS37 | J12: ='June 2026'!AT37 | K12: ='June 2026'!AU37 | L12: ='June 2026'!AV37 | M12: ='June 2026'!AW37 | N12: ='June 2026'!AX37
A13: July 2026 | B13: 31 | C13: ='July 2026'!AQ38 | D13: ='July 2026'!AR38 | E13: ='July 2026'!G38 | F13: ='July 2026'!Q38 | G13: ='July 2026'!AA38 | H13: ='July 2026'!AK38 | I13: ='July 2026'!AS38 | J13: ='July 2026'!AT38 | K13: ='July 2026'!AU38 | L13: ='July 2026'!AV38 | M13: ='July 2026'!AW38 | N13: ='July 2026'!AX38
A14: August 2026 | B14: 31 | C14: ='August 2026'!AQ38 | D14: ='August 2026'!AR38 | E14: ='August 2026'!G38 | F14: ='August 2026'!Q38 | G14: ='August 2026'!AA38 | H14: ='August 2026'!AK38 | I14: ='August 2026'!AS38 | J14: ='August 2026'!AT38 | K14: ='August 2026'!AU38 | L14: ='August 2026'!AV38 | M14: ='August 2026'!AW38 | N14: ='August 2026'!AX38
A15: TOTAL / YTD | B15: =SUM(B11:B14) | C15: =SUM(C11:C14) | D15: =SUM(D11:D14) | E15: =SUM(E11:E14) | F15: =SUM(F11:F14) | G15: =SUM(G11:G14) | H15: =SUM(H11:H14) | I15: =SUM(I11:I14) | ... N15: =SUM(N11:N14)

Sheet May 2026
A1: AHU DAILY SAVINGS & KWH COST REPORT - MAY 2026
A2: Operating Schedule: Mon-Fri 8:00 AM to 8:00 PM (12 hrs/AHU) | Sat 8:00 AM to 2:00 PM (6 hrs/AHU) | Sun Off
A3: Logic: KWH Rate = Rs. 7.45 | Hourly Rate = KWH Cost / Actual Run Hrs | Full Cost = KWH Cost + (Saved Hrs * Hourly Rate) | Saving = Saved Hrs * Hourly Rate
A5: Date & Day | C5: AHU-1 (CFM 26500) | M5: AHU-2 (CFM 26700) | W5: AHU-3 (CFM 28000) | AG5: AHU-4 (CFM 28500) | AQ5: DAILY TOTAL COMBINED SUMMARY (ALL AHUs)
A6: Date | B6: Day | C6: ON Time | D6: OFF Time | E6: Sched Hrs | F6: Actual Run Hrs | G6: Saved Hrs | H6: Consumption (KWH) | I6: Actual Cost (Rs) | J6: Cost / Hr (Rs) | K6: Full Cost 8PM (Rs) | L6: Cost Saved (Rs) | M6: ON Time | N6: OFF Time | O6: Sched Hrs | P6: Actual Run Hrs | Q6: Saved Hrs | R6: Consumption (KWH) | S6: Actual Cost (Rs) | T6: Cost / Hr (Rs) | U6: Full Cost 8PM (Rs) | V6: Cost Saved (Rs) | W6: ON Time | X6: OFF Time | Y6: Sched Hrs | Z6: Actual Run Hrs | AA6: Saved Hrs | AB6: Consumption (KWH) | AC6: Actual Cost (Rs) | AD6: Cost / Hr (Rs) | AE6: Full Cost 8PM (Rs) | AF6: Cost Saved (Rs) | AG6: ON Time | AH6: OFF Time | AI6: Sched Hrs | AJ6: Actual Run Hrs | AK6: Saved Hrs | AL6: Consumption (KWH) | AM6: Actual Cost (Rs) | AN6: Cost / Hr (Rs) | AO6: Full Cost 8PM (Rs) | AP6: Cost Saved (Rs) | AQ6: Tot Sched Hrs | AR6: Tot Actual Run Hrs | AS6: Tot Saved Hrs | AT6: Tot Consumption (KWH) | AU6: KWH Cost (Rs) | AV6: Tot Actual Cost (Rs) | AW6: Tot Full Cost 8PM (Rs) | AX6: Total Cost Saved (Rs) | AY6: Savings %
A7: 46143 | B7: Fri | C7: 0.28472222 | D7: 0.80208333 | E7: =IF(B7="Sun", 0, IF(B7="Sat", 6, 12)) | F7: =IF(OR(D7="OFF", ISBLANK(D7)), 0, (D7 - C7)*24) | G7: =IF(OR(B7="Sun", D7="OFF", ISBLANK(D7)), 0, MAX(0, (IF(B7="Sat", 14/24, 20/24) - D7)*24)) | H7: 110 | I7: =H7*7.45 | J7: =IF(F7>0, I7/F7, 0) | K7: =I7 + (G7*J7) | L7: =G7*J7 | M7: 0.28472222 | N7: 0.80208333 | O7: =IF(B7="Sun", 0, IF(B7="Sat", 6, 12)) | P7: =IF(OR(N7="OFF", ISBLANK(N7)), 0, (N7 - M7)*24) | Q7: =IF(OR(B7="Sun", N7="OFF", ISBLANK(N7)), 0, MAX(0, (IF(B7="Sat", 14/24, 20/24) - N7)*24)) | R7: 134 | S7: =R7*7.45 | T7: =IF(P7>0, S7/P7, 0) | U7: =S7 + (Q7*T7) | V7: =Q7*T7 | W7: 0.28472222 | X7: 0.74652778 | Y7: =IF(B7="Sun", 0, IF(B7="Sat", 6, 12)) | Z7: =IF(OR(X7="OFF", ISBLANK(X7)), 0, (X7 - W7)*24) | AA7: =IF(OR(B7="Sun", X7="OFF", ISBLANK(X7)), 0, MAX(0, (IF(B7="Sat", 14/24, 20/24) - X7)*24)) | AB7: 89 | AC7: =AB7*7.45 | AD7: =IF(Z7>0, AC7/Z7, 0) | AE7: =AC7 + (AA7*AD7) | AF7: =AA7*AD7 | AG7: 0.28472222 | AH7: 0.80208333 | AI7: =IF(B7="Sun", 0, IF(B7="Sat", 6, 12)) | AJ7: =IF(OR(AH7="OFF", ISBLANK(AH7)), 0, (AH7 - AG7)*24) | AK7: =IF(OR(B7="Sun", AH7="OFF", ISBLANK(AH7)), 0, MAX(0, (IF(B7="Sat", 14/24, 20/24) - AH7)*24)) | AL7: 68 | AM7: =AL7*7.45 | AN7: =IF(AJ7>0, AM7/AJ7, 0) | AO7: =AM7 + (AK7*AN7) | AP7: =AK7*AN7 | AQ7: =E7+O7+Y7+AI7 | AR7: =F7+P7+Z7+AJ7 | AS7: =G7+Q7+AA7+AK7 | AT7: =H7+R7+AB7+AL7 | AU7: =AT7*7.45 | AV7: =I7+S7+AC7+AM7 | AW7: =K7+U7+AE7+AO7 | AX7: =L7+V7+AF7+AP7 | AY7: =IF(AW7>0, AX7/AW7, 0)
A8: 46144 | B8: Sat | C8: 0.27083333 | D8: 0.83333333 | E8: =IF(B8="Sun", 0, IF(B8="Sat", 6, 12)) | F8: =IF(OR(D8="OFF", ISBLANK(D8)), 0, (D8 - C8)*24) | G8: =IF(OR(B8="Sun", D8="OFF", ISBLANK(D8)), 0, MAX(0, (IF(B8="Sat", 14/24, 20/24) - D8)*24)) | H8: 64 | I8: =H8*7.45 | J8: =IF(F8>0, I8/F8, 0) | K8: =I8 + (G8*J8) | L8: =G8*J8 | M8: 0.27083333 | N8: 0.83333333 | O8: =IF(B8="Sun", 0, IF(B8="Sat", 6, 12)) | P8: =IF(OR(N8="OFF", ISBLANK(N8)), 0, (N8 - M8)*24) | Q8: =IF(OR(B8="Sun", N8="OFF", ISBLANK(N8)), 0, MAX(0, (IF(B8="Sat", 14/24, 20/24) - N8)*24)) | R8: 77 | S8: =R8*7.45 | T8: =IF(P8>0, S8/P8, 0) | U8: =S8 + (Q8*T8) | V8: =Q8*T8 | W8: 0.27083333 | X8: 0.72916667 | Y8: =IF(B8="Sun", 0, IF(B8="Sat", 6, 12)) | Z8: =IF(OR(X8="OFF", ISBLANK(X8)), 0, (X8 - W8)*24) | AA8: =IF(OR(B8="Sun", X8="OFF", ISBLANK(X8)), 0, MAX(0, (IF(B8="Sat", 14/24, 20/24) - X8)*24)) | AB8: 62 | AC8: =AB8*7.45 | AD8: =IF(Z8>0, AC8/Z8, 0) | AE8: =AC8 + (AA8*AD8) | AF8: =AA8*AD8 | AG8: 0.27083333 | AH8: 0.83333333 | AI8: =IF(B8="Sun", 0, IF(B8="Sat", 6, 12)) | AJ8: =IF(OR(AH8="OFF", ISBLANK(AH8)), 0, (AH8 - AG8)*24) | AK8: =IF(OR(B8="Sun", AH8="OFF", ISBLANK(AH8)), 0, MAX(0, (IF(B8="Sat", 14/24, 20/24) - AH8)*24)) | AL8: 46 | AM8: =AL8*7.45 | AN8: =IF(AJ8>0, AM8/AJ8, 0) | AO8: =AM8 + (AK8*AN8) | AP8: =AK8*AN8 | AQ8: =E8+O8+Y8+AI8 | AR8: =F8+P8+Z8+AJ8 | AS8: =G8+Q8+AA8+AK8 | AT8: =H8+R8+AB8+AL8 | AU8: =AT8*7.45 | AV8: =I8+S8+AC8+AM8 | AW8: =K8+U8+AE8+AO8 | AX8: =L8+V8+AF8+AP8 | AY8: =IF(AW8>0, AX8/AW8, 0)
A9: 46145 | B9: Sun | C9: 0 | D9: 0 | E9: =IF(B9="Sun", 0, IF(B9="Sat", 6, 12)) | F9: =IF(OR(D9="OFF", ISBLANK(D9)), 0, (D9 - C9)*24) | G9: =IF(OR(B9="Sun", D9="OFF", ISBLANK(D9)), 0, MAX(0, (IF(B9="Sat", 14/24, 20/24) - D9)*24)) | H9: 0 | I9: =H9*7.45 | J9: =IF(F9>0, I9/F9, 0) | K9: =I9 + (G9*J9) | L9: =G9*J9 | M9: 0 | N9: 0 | O9: =IF(B9="Sun", 0, IF(B9="Sat", 6, 12)) | P9: =IF(OR(N9="OFF", ISBLANK(N9)), 0, (N9 - M9)*24) | Q9: =IF(OR(B9="Sun", N9="OFF", ISBLANK(N9)), 0, MAX(0, (IF(B9="Sat", 14/24, 20/24) - N9)*24)) | R9: 0 | S9: =R9*7.45 | T9: =IF(P9>0, S9/P9, 0) | U9: =S9 + (Q9*T9) | V9: =Q9*T9 | W9: 0 | X9: 0 | Y9: =IF(B9="Sun", 0, IF(B9="Sat", 6, 12)) | Z9: =IF(OR(X9="OFF", ISBLANK(X9)), 0, (X9 - W9)*24) | AA9: =IF(OR(B9="Sun", X9="OFF", ISBLANK(X9)), 0, MAX(0, (IF(B9="Sat", 14/24, 20/24) - X9)*24)) | AB9: 0 | AC9: =AB9*7.45 | AD9: =IF(Z9>0, AC9/Z9, 0) | AE9: =AC9 + (AA9*AD9) | AF9: =AA9*AD9 | AG9: 0 | AH9: 0 | AI9: =IF(B9="Sun", 0, IF(B9="Sat", 6, 12)) | AJ9: =IF(OR(AH9="OFF", ISBLANK(AH9)), 0, (AH9 - AG9)*24) | AK9: =IF(OR(B9="Sun", AH9="OFF", ISBLANK(AH9)), 0, MAX(0, (IF(B9="Sat", 14/24, 20/24) - AH9)*24)) | AL9: 0 | AM9: =AL9*7.45 | AN9: =IF(AJ9>0, AM9/AJ9, 0) | AO9: =AM9 + (AK9*AN9) | AP9: =AK9*AN9 | AQ9: =E9+O9+Y9+AI9 | AR9: =F9+P9+Z9+AJ9 | AS9: =G9+Q9+AA9+AK9 | AT9: =H9+R9+AB9+AL9 | AU9: =AT9*7.45 | AV9: =I9+S9+AC9+AM9 | AW9: =K9+U9+AE9+AO9 | AX9: =L9+V9+AF9+AP9 | AY9: =IF(AW9>0, AX9/AW9, 0)
A10: 46146 | B10: Mon | C10: 0.27361111 | D10: 0.91666667 | E10: =IF(B10="Sun", 0, IF(B10="Sat", 6, 12)) | F10: =IF(OR(D10="OFF", ISBLANK(D10)), 0, (D10 - C10)*24) | G10: =IF(OR(B10="Sun", D10="OFF", ISBLANK(D10)), 0, MAX(0, (IF(B10="Sat", 14/24, 20/24) - D10)*24)) | H10: 60 | I10: =H10*7.45 | J10: =IF(F10>0, I10/F10, 0) | K10: =I10 + (G10*J10) | L10: =G10*J10 | M10: 0.27361111 | N10: 0.91666667 | O10: =IF(B10="Sun", 0, IF(B10="Sat", 6, 12)) | P10: =IF(OR(N10="OFF", ISBLANK(N10)), 0, (N10 - M10)*24) | Q10: =IF(OR(B10="Sun", N10="OFF", ISBLANK(N10)), 0, MAX(0, (IF(B10="Sat", 14/24, 20/24) - N10)*24)) | R10: 88 | S10: =R10*7.45 | T10: =IF(P10>0, S10/P10, 0) | U10: =S10 + (Q10*T10) | V10: =Q10*T10 | W10: 0.27361111 | X10: 0.81944444 | Y10: =IF(B10="Sun", 0, IF(B10="Sat", 6, 12)) | Z10: =IF(OR(X10="OFF", ISBLANK(X10)), 0, (X10 - W10)*24) | AA10: =IF(OR(B10="Sun", X10="OFF", ISBLANK(X10)), 0, MAX(0, (IF(B10="Sat", 14/24, 20/24) - X10)*24)) | AB10: 86 | AC10: =AB10*7.45 | AD10: =IF(Z10>0, AC10/Z10, 0) | AE10: =AC10 + (AA10*AD10) | AF10: =AA10*AD10 | AG10: 0.27361111 | AH10: 0.91666667 | AI10: =IF(B10="Sun", 0, IF(B10="Sat", 6, 12)) | AJ10: =IF(OR(AH10="OFF", ISBLANK(AH10)), 0, (AH10 - AG10)*24) | AK10: =IF(OR(B10="Sun", AH10="OFF", ISBLANK(AH10)), 0, MAX(0, (IF(B10="Sat", 14/24, 20/24) - AH10)*24)) | AL10: 66 | AM10: =AL10*7.45 | AN10: =IF(AJ10>0, AM10/AJ10, 0) | AO10: =AM10 + (AK10*AN10) | AP10: =AK10*AN10 | AQ10: =E10+O10+Y10+AI10 | AR10: =F10+P10+Z10+AJ10 | AS10: =G10+Q10+AA10+AK10 | AT10: =H10+R10+AB10+AL10 | AU10: =AT10*7.45 | AV10: =I10+S10+AC10+AM10 | AW10: =K10+U10+AE10+AO10 | AX10: =L10+V10+AF10+AP10 | AY10: =IF(AW10>0, AX10/AW10, 0)
A11: 46147 | B11: Tue | C11: 0.27777778 | D11: 0.95833333 | E11: =IF(B11="Sun", 0, IF(B11="Sat", 6, 12)) | F11: =IF(OR(D11="OFF", ISBLANK(D11)), 0, (D11 - C11)*24) | G11: =IF(OR(B11="Sun", D11="OFF", ISBLANK(D11)), 0, MAX(0, (IF(B11="Sat", 14/24, 20/24) - D11)*24)) | H11: 67 | I11: =H11*7.45 | J11: =IF(F11>0, I11/F11, 0) | K11: =I11 + (G11*J11) | L11: =G11*J11 | M11: 0.27777778 | N11: 0.95833333 | O11: =IF(B11="Sun", 0, IF(B11="Sat", 6, 12)) | P11: =IF(OR(N11="OFF", ISBLANK(N11)), 0, (N11 - M11)*24) | Q11: =IF(OR(B11="Sun", N11="OFF", ISBLANK(N11)), 0, MAX(0, (IF(B11="Sat", 14/24, 20/24) - N11)*24)) | R11: 93 | S11: =R11*7.45 | T11: =IF(P11>0, S11/P11, 0) | U11: =S11 + (Q11*T11) | V11: =Q11*T11 | W11: 0.27777778 | X11: 0.80555556 | Y11: =IF(B11="Sun", 0, IF(B11="Sat", 6, 12)) | Z11: =IF(OR(X11="OFF", ISBLANK(X11)), 0, (X11 - W11)*24) | AA11: =IF(OR(B11="Sun", X11="OFF", ISBLANK(X11)), 0, MAX(0, (IF(B11="Sat", 14/24, 20/24) - X11)*24)) | AB11: 94 | AC11: =AB11*7.45 | AD11: =IF(Z11>0, AC11/Z11, 0) | AE11: =AC11 + (AA11*AD11) | AF11: =AA11*AD11 | AG11: 0.27777778 | AH11: 0.95833333 | AI11: =IF(B11="Sun", 0, IF(B11="Sat", 6, 12)) | AJ11: =IF(OR(AH11="OFF", ISBLANK(AH11)), 0, (AH11 - AG11)*24) | AK11: =IF(OR(B11="Sun", AH11="OFF", ISBLANK(AH11)), 0, MAX(0, (IF(B11="Sat", 14/24, 20/24) - AH11)*24)) | AL11: 68 | AM11: =AL11*7.45 | AN11: =IF(AJ11>0, AM11/AJ11, 0) | AO11: =AM11 + (AK11*AN11) | AP11: =AK11*AN11 | AQ11: =E11+O11+Y11+AI11 | AR11: =F11+P11+Z11+AJ11 | AS11: =G11+Q11+AA11+AK11 | AT11: =H11+R11+AB11+AL11 | AU11: =AT11*7.45 | AV11: =I11+S11+AC11+AM11 | AW11: =K11+U11+AE11+AO11 | AX11: =L11+V11+AF11+AP11 | AY11: =IF(AW11>0, AX11/AW11, 0)
A12: 46148 | B12: Wed | C12: 0.31944444 | D12: 0.77430556 | E12: =IF(B12="Sun", 0, IF(B12="Sat", 6, 12)) | F12: =IF(OR(D12="OFF", ISBLANK(D12)), 0, (D12 - C12)*24) | G12: =IF(OR(B12="Sun", D12="OFF", ISBLANK(D12)), 0, MAX(0, (IF(B12="Sat", 14/24, 20/24) - D12)*24)) | H12: 58 | I12: =H12*7.45 | J12: =IF(F12>0, I12/F12, 0) | K12: =I12 + (G12*J12) | L12: =G12*J12 | M12: 0.31944444 | N12: 0.77430556 | O12: =IF(B12="Sun", 0, IF(B12="Sat", 6, 12)) | P12: =IF(OR(N12="OFF", ISBLANK(N12)), 0, (N12 - M12)*24) | Q12: =IF(OR(B12="Sun", N12="OFF", ISBLANK(N12)), 0, MAX(0, (IF(B12="Sat", 14/24, 20/24) - N12)*24)) | R12: 69 | S12: =R12*7.45 | T12: =IF(P12>0, S12/P12, 0) | U12: =S12 + (Q12*T12) | V12: =Q12*T12 | W12: 0.31944444 | X12: 0.77430556 | Y12: =IF(B12="Sun", 0, IF(B12="Sat", 6, 12)) | Z12: =IF(OR(X12="OFF", ISBLANK(X12)), 0, (X12 - W12)*24) | AA12: =IF(OR(B12="Sun", X12="OFF", ISBLANK(X12)), 0, MAX(0, (IF(B12="Sat", 14/24, 20/24) - X12)*24)) | AB12: 70 | AC12: =AB12*7.45 | AD12: =IF(Z12>0, AC12/Z12, 0) | AE12: =AC12 + (AA12*AD12) | AF12: =AA12*AD12 | AG12: 0.31944444 | AH12: 0.77430556 | AI12: =IF(B12="Sun", 0, IF(B12="Sat", 6, 12)) | AJ12: =IF(OR(AH12="OFF", ISBLANK(AH12)), 0, (AH12 - AG12)*24) | AK12: =IF(OR(B12="Sun", AH12="OFF", ISBLANK(AH12)), 0, MAX(0, (IF(B12="Sat", 14/24, 20/24) - AH12)*24)) | AL12: 55 | AM12: =AL12*7.45 | AN12: =IF(AJ12>0, AM12/AJ12, 0) | AO12: =AM12 + (AK12*AN12) | AP12: =AK12*AN12 | AQ12: =E12+O12+Y12+AI12 | AR12: =F12+P12+Z12+AJ12 | AS12: =G12+Q12+AA12+AK12 | AT12: =H12+R12+AB12+AL12 | AU12: =AT12*7.45 | AV12: =I12+S12+AC12+AM12 | AW12: =K12+U12+AE12+AO12 | AX12: =L12+V12+AF12+AP12 | AY12: =IF(AW12>0, AX12/AW12, 0)
A13: 46149 | B13: Thu | C13: 0.32638889 | D13: 0.83055556 | E13: =IF(B13="Sun", 0, IF(B13="Sat", 6, 12)) | F13: =IF(OR(D13="OFF", ISBLANK(D13)), 0, (D13 - C13)*24) | G13: =IF(OR(B13="Sun", D13="OFF", ISBLANK(D13)), 0, MAX(0, (IF(B13="Sat", 14/24, 20/24) - D13)*24)) | H13: 60 | I13: =H13*7.45 | J13: =IF(F13>0, I13/F13, 0) | K13: =I13 + (G13*J13) | L13: =G13*J13 | M13: 0.32638889 | N13: 0.83055556 | O13: =IF(B13="Sun", 0, IF(B13="Sat", 6, 12)) | P13: =IF(OR(N13="OFF", ISBLANK(N13)), 0, (N13 - M13)*24) | Q13: =IF(OR(B13="Sun", N13="OFF", ISBLANK(N13)), 0, MAX(0, (IF(B13="Sat", 14/24, 20/24) - N13)*24)) | R13: 65 | S13: =R13*7.45 | T13: =IF(P13>0, S13/P13, 0) | U13: =S13 + (Q13*T13) | V13: =Q13*T13 | W13: 0.32638889 | X13: 0.83055556 | Y13: =IF(B13="Sun", 0, IF(B13="Sat", 6, 12)) | Z13: =IF(OR(X13="OFF", ISBLANK(X13)), 0, (X13 - W13)*24) | AA13: =IF(OR(B13="Sun", X13="OFF", ISBLANK(X13)), 0, MAX(0, (IF(B13="Sat", 14/24, 20/24) - X13)*24)) | AB13: 81 | AC13: =AB13*7.45 | AD13: =IF(Z13>0, AC13/Z13, 0) | AE13: =AC13 + (AA13*AD13) | AF13: =AA13*AD13 | AG13: 0.32638889 | AH13: 0.83055556 | AI13: =IF(B13="Sun", 0, IF(B13="Sat", 6, 12)) | AJ13: =IF(OR(AH13="OFF", ISBLANK(AH13)), 0, (AH13 - AG13)*24) | AK13: =IF(OR(B13="Sun", AH13="OFF", ISBLANK(AH13)), 0, MAX(0, (IF(B13="Sat", 14/24, 20/24) - AH13)*24)) | AL13: 62 | AM13: =AL13*7.45 | AN13: =IF(AJ13>0, AM13/AJ13, 0) | AO13: =AM13 + (AK13*AN13) | AP13: =AK13*AN13 | AQ13: =E13+O13+Y13+AI13 | AR13: =F13+P13+Z13+AJ13 | AS13: =G13+Q13+AA13+AK13 | AT13: =H13+R13+AB13+AL13 | AU13: =AT13*7.45 | AV13: =I13+S13+AC13+AM13 | AW13: =K13+U13+AE13+AO13 | AX13: =L13+V13+AF13+AP13 | AY13: =IF(AW13>0, AX13/AW13, 0)
A14: 46150 | B14: Fri | C14: 0.32291667 | D14: 0.75694444 | E14: =IF(B14="Sun", 0, IF(B14="Sat", 6, 12)) | F14: =IF(OR(D14="OFF", ISBLANK(D14)), 0, (D14 - C14)*24) | G14: =IF(OR(B14="Sun", D14="OFF", ISBLANK(D14)), 0, MAX(0, (IF(B14="Sat", 14/24, 20/24) - D14)*24)) | H14: 55 | I14: =H14*7.45 | J14: =IF(F14>0, I14/F14, 0) | K14: =I14 + (G14*J14) | L14: =G14*J14 | M14: 0.32291667 | N14: 0.81944444 | O14: =IF(B14="Sun", 0, IF(B14="Sat", 6, 12)) | P14: =IF(OR(N14="OFF", ISBLANK(N14)), 0, (N14 - M14)*24) | Q14: =IF(OR(B14="Sun", N14="OFF", ISBLANK(N14)), 0, MAX(0, (IF(B14="Sat", 14/24, 20/24) - N14)*24)) | R14: 65 | S14: =R14*7.45 | T14: =IF(P14>0, S14/P14, 0) | U14: =S14 + (Q14*T14) | V14: =Q14*T14 | W14: 0.32291667 | X14: 0.73333333 | Y14: =IF(B14="Sun", 0, IF(B14="Sat", 6, 12)) | Z14: =IF(OR(X14="OFF", ISBLANK(X14)), 0, (X14 - W14)*24) | AA14: =IF(OR(B14="Sun", X14="OFF", ISBLANK(X14)), 0, MAX(0, (IF(B14="Sat", 14/24, 20/24) - X14)*24)) | AB14: 69 | AC14: =AB14*7.45 | AD14: =IF(Z14>0, AC14/Z14, 0) | AE14: =AC14 + (AA14*AD14) | AF14: =AA14*AD14 | AG14: 0.32291667 | AH14: 0.75694444 | AI14: =IF(B14="Sun", 0, IF(B14="Sat", 6, 12)) | AJ14: =IF(OR(AH14="OFF", ISBLANK(AH14)), 0, (AH14 - AG14)*24) | AK14: =IF(OR(B14="Sun", AH14="OFF", ISBLANK(AH14)), 0, MAX(0, (IF(B14="Sat", 14/24, 20/24) - AH14)*24)) | AL14: 54 | AM14: =AL14*7.45 | AN14: =IF(AJ14>0, AM14/AJ14, 0) | AO14: =AM14 + (AK14*AN14) | AP14: =AK14*AN14 | AQ14: =E14+O14+Y14+AI14 | AR14: =F14+P14+Z14+AJ14 | AS14: =G14+Q14+AA14+AK14 | AT14: =H14+R14+AB14+AL14 | AU14: =AT14*7.45 | AV14: =I14+S14+AC14+AM14 | AW14: =K14+U14+AE14+AO14 | AX14: =L14+V14+AF14+AP14 | AY14: =IF(AW14>0, AX14/AW14, 0)
A15: 46151 | B15: Sat | C15: 0.32777778 | D15: 0.58541667 | E15: =IF(B15="Sun", 0, IF(B15="Sat", 6, 12)) | F15: =IF(OR(D15="OFF", ISBLANK(D15)), 0, (D15 - C15)*24) | G15: =IF(OR(B15="Sun", D15="OFF", ISBLANK(D15)), 0, MAX(0, (IF(B15="Sat", 14/24, 20/24) - D15)*24)) | H15: 32 | I15: =H15*7.45 | J15: =IF(F15>0, I15/F15, 0) | K15: =I15 + (G15*J15) | L15: =G15*J15 | M15: 0.32777778 | N15: 0.58541667 | O15: =IF(B15="Sun", 0, IF(B15="Sat", 6, 12)) | P15: =IF(OR(N15="OFF", ISBLANK(N15)), 0, (N15 - M15)*24) | Q15: =IF(OR(B15="Sun", N15="OFF", ISBLANK(N15)), 0, MAX(0, (IF(B15="Sat", 14/24, 20/24) - N15)*24)) | R15: 33 | S15: =R15*7.45 | T15: =IF(P15>0, S15/P15, 0) | U15: =S15 + (Q15*T15) | V15: =Q15*T15 | W15: 0.32777778 | X15: 0.58541667 | Y15: =IF(B15="Sun", 0, IF(B15="Sat", 6, 12)) | Z15: =IF(OR(X15="OFF", ISBLANK(X15)), 0, (X15 - W15)*24) | AA15: =IF(OR(B15="Sun", X15="OFF", ISBLANK(X15)), 0, MAX(0, (IF(B15="Sat", 14/24, 20/24) - X15)*24)) | AB15: 71 | AC15: =AB15*7.45 | AD15: =IF(Z15>0, AC15/Z15, 0) | AE15: =AC15 + (AA15*AD15) | AF15: =AA15*AD15 | AG15: 0.32777778 | AH15: 0.58541667 | AI15: =IF(B15="Sun", 0, IF(B15="Sat", 6, 12)) | AJ15: =IF(OR(AH15="OFF", ISBLANK(AH15)), 0, (AH15 - AG15)*24) | AK15: =IF(OR(B15="Sun", AH15="OFF", ISBLANK(AH15)), 0, MAX(0, (IF(B15="Sat", 14/24, 20/24) - AH15)*24)) | AL15: 31 | AM15: =AL15*7.45 | AN15: =IF(AJ15>0, AM15/AJ15, 0) | AO15: =AM15 + (AK15*AN15) | AP15: =AK15*AN15 | AQ15: =E15+O15+Y15+AI15 | AR15: =F15+P15+Z15+AJ15 | AS15: =G15+Q15+AA15+AK15 | AT15: =H15+R15+AB15+AL15 | AU15: =AT15*7.45 | AV15: =I15+S15+AC15+AM15 | AW15: =K15+U15+AE15+AO15 | AX15: =L15+V15+AF15+AP15 | AY15: =IF(AW15>0, AX15/AW15, 0)
A16: 46152 | B16: Sun | C16: OFF | D16: OFF | E16: =IF(B16="Sun", 0, IF(B16="Sat", 6, 12)) | F16: =IF(OR(D16="OFF", ISBLANK(D16)), 0, (D16 - C16)*24) | G16: =IF(OR(B16="Sun", D16="OFF", ISBLANK(D16)), 0, MAX(0, (IF(B16="Sat", 14/24, 20/24) - D16)*24)) | H16: 0 | I16: =H16*7.45 | J16: =IF(F16>0, I16/F16, 0) | K16: =I16 + (G16*J16) | L16: =G16*J16 | M16: OFF | N16: OFF | O16: =IF(B16="Sun", 0, IF(B16="Sat", 6, 12)) | P16: =IF(OR(N16="OFF", ISBLANK(N16)), 0, (N16 - M16)*24) | Q16: =IF(OR(B16="Sun", N16="OFF", ISBLANK(N16)), 0, MAX(0, (IF(B16="Sat", 14/24, 20/24) - N16)*24)) | R16: 0 | S16: =R16*7.45 | T16: =IF(P16>0, S16/P16, 0) | U16: =S16 + (Q16*T16) | V16: =Q16*T16 | W16: OFF | X16: OFF | Y16: =IF(B16="Sun", 0, IF(B16="Sat", 6, 12)) | Z16: =IF(OR(X16="OFF", ISBLANK(X16)), 0, (X16 - W16)*24) | AA16: =IF(OR(B16="Sun", X16="OFF", ISBLANK(X16)), 0, MAX(0, (IF(B16="Sat", 14/24, 20/24) - X16)*24)) | AB16: 0 | AC16: =AB16*7.45 | AD16: =IF(Z16>0, AC16/Z16, 0) | AE16: =AC16 + (AA16*AD16) | AF16: =AA16*AD16 | AG16: OFF | AH16: OFF | AI16: =IF(B16="Sun", 0, IF(B16="Sat", 6, 12)) | AJ16: =IF(OR(AH16="OFF", ISBLANK(AH16)), 0, (AH16 - AG16)*24) | AK16: =IF(OR(B16="Sun", AH16="OFF", ISBLANK(AH16)), 0, MAX(0, (IF(B16="Sat", 14/24, 20/24) - AH16)*24)) | AL16: 0 | AM16: =AL16*7.45 | AN16: =IF(AJ16>0, AM16/AJ16, 0) | AO16: =AM16 + (AK16*AN16) | AP16: =AK16*AN16 | AQ16: =E16+O16+Y16+AI16 | AR16: =F16+P16+Z16+AJ16 | AS16: =G16+Q16+AA16+AK16 | AT16: =H16+R16+AB16+AL16 | AU16: =AT16*7.45 | AV16: =I16+S16+AC16+AM16 | AW16: =K16+U16+AE16+AO16 | AX16: =L16+V16+AF16+AP16 | AY16: =IF(AW16>0, AX16/AW16, 0)
A17: 46153 | B17: Mon | C17: 0.31666667 | D17: 0.79305556 | E17: =IF(B17="Sun", 0, IF(B17="Sat", 6, 12)) | F17: =IF(OR(D17="OFF", ISBLANK(D17)), 0, (D17 - C17)*24) | G17: =IF(OR(B17="Sun", D17="OFF", ISBLANK(D17)), 0, MAX(0, (IF(B17="Sat", 14/24, 20/24) - D17)*24)) | H17: 60 | I17: =H17*7.45 | J17: =IF(F17>0, I17/F17, 0) | K17: =I17 + (G17*J17) | L17: =G17*J17 | M17: 0.31666667 | N17: 0.79305556 | O17: =IF(B17="Sun", 0, IF(B17="Sat", 6, 12)) | P17: =IF(OR(N17="OFF", ISBLANK(N17)), 0, (N17 - M17)*24) | Q17: =IF(OR(B17="Sun", N17="OFF", ISBLANK(N17)), 0, MAX(0, (IF(B17="Sat", 14/24, 20/24) - N17)*24)) | R17: 59 | S17: =R17*7.45 | T17: =IF(P17>0, S17/P17, 0) | U17: =S17 + (Q17*T17) | V17: =Q17*T17 | W17: 0.31666667 | X17: 0.79305556 | Y17: =IF(B17="Sun", 0, IF(B17="Sat", 6, 12)) | Z17: =IF(OR(X17="OFF", ISBLANK(X17)), 0, (X17 - W17)*24) | AA17: =IF(OR(B17="Sun", X17="OFF", ISBLANK(X17)), 0, MAX(0, (IF(B17="Sat", 14/24, 20/24) - X17)*24)) | AB17: 81 | AC17: =AB17*7.45 | AD17: =IF(Z17>0, AC17/Z17, 0) | AE17: =AC17 + (AA17*AD17) | AF17: =AA17*AD17 | AG17: 0.31666667 | AH17: 0.79305556 | AI17: =IF(B17="Sun", 0, IF(B17="Sat", 6, 12)) | AJ17: =IF(OR(AH17="OFF", ISBLANK(AH17)), 0, (AH17 - AG17)*24) | AK17: =IF(OR(B17="Sun", AH17="OFF", ISBLANK(AH17)), 0, MAX(0, (IF(B17="Sat", 14/24, 20/24) - AH17)*24)) | AL17: 1 | AM17: =AL17*7.45 | AN17: =IF(AJ17>0, AM17/AJ17, 0) | AO17: =AM17 + (AK17*AN17) | AP17: =AK17*AN17 | AQ17: =E17+O17+Y17+AI17 | AR17: =F17+P17+Z17+AJ17 | AS17: =G17+Q17+AA17+AK17 | AT17: =H17+R17+AB17+AL17 | AU17: =AT17*7.45 | AV17: =I17+S17+AC17+AM17 | AW17: =K17+U17+AE17+AO17 | AX17: =L17+V17+AF17+AP17 | AY17: =IF(AW17>0, AX17/AW17, 0)
A18: 46154 | B18: Tue | C18: 0.325 | D18: 0.79166667 | E18: =IF(B18="Sun", 0, IF(B18="Sat", 6, 12)) | F18: =IF(OR(D18="OFF", ISBLANK(D18)), 0, (D18 - C18)*24) | G18: =IF(OR(B18="Sun", D18="OFF", ISBLANK(D18)), 0, MAX(0, (IF(B18="Sat", 14/24, 20/24) - D18)*24)) | H18: 58 | I18: =H18*7.45 | J18: =IF(F18>0, I18/F18, 0) | K18: =I18 + (G18*J18) | L18: =G18*J18 | M18: 0.325 | N18: 0.79166667 | O18: =IF(B18="Sun", 0, IF(B18="Sat", 6, 12)) | P18: =IF(OR(N18="OFF", ISBLANK(N18)), 0, (N18 - M18)*24) | Q18: =IF(OR(B18="Sun", N18="OFF", ISBLANK(N18)), 0, MAX(0, (IF(B18="Sat", 14/24, 20/24) - N18)*24)) | R18: 57 | S18: =R18*7.45 | T18: =IF(P18>0, S18/P18, 0) | U18: =S18 + (Q18*T18) | V18: =Q18*T18 | W18: 0.325 | X18: 0.79166667 | Y18: =IF(B18="Sun", 0, IF(B18="Sat", 6, 12)) | Z18: =IF(OR(X18="OFF", ISBLANK(X18)), 0, (X18 - W18)*24) | AA18: =IF(OR(B18="Sun", X18="OFF", ISBLANK(X18)), 0, MAX(0, (IF(B18="Sat", 14/24, 20/24) - X18)*24)) | AB18: 73 | AC18: =AB18*7.45 | AD18: =IF(Z18>0, AC18/Z18, 0) | AE18: =AC18 + (AA18*AD18) | AF18: =AA18*AD18 | AG18: 0.325 | AH18: 0.75555556 | AI18: =IF(B18="Sun", 0, IF(B18="Sat", 6, 12)) | AJ18: =IF(OR(AH18="OFF", ISBLANK(AH18)), 0, (AH18 - AG18)*24) | AK18: =IF(OR(B18="Sun", AH18="OFF", ISBLANK(AH18)), 0, MAX(0, (IF(B18="Sat", 14/24, 20/24) - AH18)*24)) | AL18: 50 | AM18: =AL18*7.45 | AN18: =IF(AJ18>0, AM18/AJ18, 0) | AO18: =AM18 + (AK18*AN18) | AP18: =AK18*AN18 | AQ18: =E18+O18+Y18+AI18 | AR18: =F18+P18+Z18+AJ18 | AS18: =G18+Q18+AA18+AK18 | AT18: =H18+R18+AB18+AL18 | AU18: =AT18*7.45 | AV18: =I18+S18+AC18+AM18 | AW18: =K18+U18+AE18+AO18 | AX18: =L18+V18+AF18+AP18 | AY18: =IF(AW18>0, AX18/AW18, 0)
A19: 46155 | B19: Wed | C19: 0.30902778 | D19: 0.75486111 | E19: =IF(B19="Sun", 0, IF(B19="Sat", 6, 12)) | F19: =IF(OR(D19="OFF", ISBLANK(D19)), 0, (D19 - C19)*24) | G19: =IF(OR(B19="Sun", D19="OFF", ISBLANK(D19)), 0, MAX(0, (IF(B19="Sat", 14/24, 20/24) - D19)*24)) | H19: 55 | I19: =H19*7.45 | J19: =IF(F19>0, I19/F19, 0) | K19: =I19 + (G19*J19) | L19: =G19*J19 | M19: 0.30902778 | N19: 0.79791667 | O19: =IF(B19="Sun", 0, IF(B19="Sat", 6, 12)) | P19: =IF(OR(N19="OFF", ISBLANK(N19)), 0, (N19 - M19)*24) | Q19: =IF(OR(B19="Sun", N19="OFF", ISBLANK(N19)), 0, MAX(0, (IF(B19="Sat", 14/24, 20/24) - N19)*24)) | R19: 59 | S19: =R19*7.45 | T19: =IF(P19>0, S19/P19, 0) | U19: =S19 + (Q19*T19) | V19: =Q19*T19 | W19: 0.30902778 | X19: 0.79791667 | Y19: =IF(B19="Sun", 0, IF(B19="Sat", 6, 12)) | Z19: =IF(OR(X19="OFF", ISBLANK(X19)), 0, (X19 - W19)*24) | AA19: =IF(OR(B19="Sun", X19="OFF", ISBLANK(X19)), 0, MAX(0, (IF(B19="Sat", 14/24, 20/24) - X19)*24)) | AB19: 66 | AC19: =AB19*7.45 | AD19: =IF(Z19>0, AC19/Z19, 0) | AE19: =AC19 + (AA19*AD19) | AF19: =AA19*AD19 | AG19: 0.30902778 | AH19: 0.73055556 | AI19: =IF(B19="Sun", 0, IF(B19="Sat", 6, 12)) | AJ19: =IF(OR(AH19="OFF", ISBLANK(AH19)), 0, (AH19 - AG19)*24) | AK19: =IF(OR(B19="Sun", AH19="OFF", ISBLANK(AH19)), 0, MAX(0, (IF(B19="Sat", 14/24, 20/24) - AH19)*24)) | AL19: 57 | AM19: =AL19*7.45 | AN19: =IF(AJ19>0, AM19/AJ19, 0) | AO19: =AM19 + (AK19*AN19) | AP19: =AK19*AN19 | AQ19: =E19+O19+Y19+AI19 | AR19: =F19+P19+Z19+AJ19 | AS19: =G19+Q19+AA19+AK19 | AT19: =H19+R19+AB19+AL19 | AU19: =AT19*7.45 | AV19: =I19+S19+AC19+AM19 | AW19: =K19+U19+AE19+AO19 | AX19: =L19+V19+AF19+AP19 | AY19: =IF(AW19>0, AX19/AW19, 0)
A20: 46156 | B20: Thu | C20: 0.3125 | D20: 0.82638889 | E20: =IF(B20="Sun", 0, IF(B20="Sat", 6, 12)) | F20: =IF(OR(D20="OFF", ISBLANK(D20)), 0, (D20 - C20)*24) | G20: =IF(OR(B20="Sun", D20="OFF", ISBLANK(D20)), 0, MAX(0, (IF(B20="Sat", 14/24, 20/24) - D20)*24)) | H20: 64 | I20: =H20*7.45 | J20: =IF(F20>0, I20/F20, 0) | K20: =I20 + (G20*J20) | L20: =G20*J20 | M20: 0.3125 | N20: 0.82638889 | O20: =IF(B20="Sun", 0, IF(B20="Sat", 6, 12)) | P20: =IF(OR(N20="OFF", ISBLANK(N20)), 0, (N20 - M20)*24) | Q20: =IF(OR(B20="Sun", N20="OFF", ISBLANK(N20)), 0, MAX(0, (IF(B20="Sat", 14/24, 20/24) - N20)*24)) | R20: 63 | S20: =R20*7.45 | T20: =IF(P20>0, S20/P20, 0) | U20: =S20 + (Q20*T20) | V20: =Q20*T20 | W20: 0.3125 | X20: 0.75833333 | Y20: =IF(B20="Sun", 0, IF(B20="Sat", 6, 12)) | Z20: =IF(OR(X20="OFF", ISBLANK(X20)), 0, (X20 - W20)*24) | AA20: =IF(OR(B20="Sun", X20="OFF", ISBLANK(X20)), 0, MAX(0, (IF(B20="Sat", 14/24, 20/24) - X20)*24)) | AB20: 61 | AC20: =AB20*7.45 | AD20: =IF(Z20>0, AC20/Z20, 0) | AE20: =AC20 + (AA20*AD20) | AF20: =AA20*AD20 | AG20: 0.3125 | AH20: 0.75833333 | AI20: =IF(B20="Sun", 0, IF(B20="Sat", 6, 12)) | AJ20: =IF(OR(AH20="OFF", ISBLANK(AH20)), 0, (AH20 - AG20)*24) | AK20: =IF(OR(B20="Sun", AH20="OFF", ISBLANK(AH20)), 0, MAX(0, (IF(B20="Sat", 14/24, 20/24) - AH20)*24)) | AL20: 55 | AM20: =AL20*7.45 | AN20: =IF(AJ20>0, AM20/AJ20, 0) | AO20: =AM20 + (AK20*AN20) | AP20: =AK20*AN20 | AQ20: =E20+O20+Y20+AI20 | AR20: =F20+P20+Z20+AJ20 | AS20: =G20+Q20+AA20+AK20 | AT20: =H20+R20+AB20+AL20 | AU20: =AT20*7.45 | AV20: =I20+S20+AC20+AM20 | AW20: =K20+U20+AE20+AO20 | AX20: =L20+V20+AF20+AP20 | AY20: =IF(AW20>0, AX20/AW20, 0)
A21: 46157 | B21: Fri | C21: 0.3125 | D21: 0.79791667 | E21: =IF(B21="Sun", 0, IF(B21="Sat", 6, 12)) | F21: =IF(OR(D21="OFF", ISBLANK(D21)), 0, (D21 - C21)*24) | G21: =IF(OR(B21="Sun", D21="OFF", ISBLANK(D21)), 0, MAX(0, (IF(B21="Sat", 14/24, 20/24) - D21)*24)) | H21: 62 | I21: =H21*7.45 | J21: =IF(F21>0, I21/F21, 0) | K21: =I21 + (G21*J21) | L21: =G21*J21 | M21: 0.3125 | N21: 0.83333333 | O21: =IF(B21="Sun", 0, IF(B21="Sat", 6, 12)) | P21: =IF(OR(N21="OFF", ISBLANK(N21)), 0, (N21 - M21)*24) | Q21: =IF(OR(B21="Sun", N21="OFF", ISBLANK(N21)), 0, MAX(0, (IF(B21="Sat", 14/24, 20/24) - N21)*24)) | R21: 66 | S21: =R21*7.45 | T21: =IF(P21>0, S21/P21, 0) | U21: =S21 + (Q21*T21) | V21: =Q21*T21 | W21: 0.3125 | X21: 0.79791667 | Y21: =IF(B21="Sun", 0, IF(B21="Sat", 6, 12)) | Z21: =IF(OR(X21="OFF", ISBLANK(X21)), 0, (X21 - W21)*24) | AA21: =IF(OR(B21="Sun", X21="OFF", ISBLANK(X21)), 0, MAX(0, (IF(B21="Sat", 14/24, 20/24) - X21)*24)) | AB21: 66 | AC21: =AB21*7.45 | AD21: =IF(Z21>0, AC21/Z21, 0) | AE21: =AC21 + (AA21*AD21) | AF21: =AA21*AD21 | AG21: 0.3125 | AH21: 0.7125 | AI21: =IF(B21="Sun", 0, IF(B21="Sat", 6, 12)) | AJ21: =IF(OR(AH21="OFF", ISBLANK(AH21)), 0, (AH21 - AG21)*24) | AK21: =IF(OR(B21="Sun", AH21="OFF", ISBLANK(AH21)), 0, MAX(0, (IF(B21="Sat", 14/24, 20/24) - AH21)*24)) | AL21: 51 | AM21: =AL21*7.45 | AN21: =IF(AJ21>0, AM21/AJ21, 0) | AO21: =AM21 + (AK21*AN21) | AP21: =AK21*AN21 | AQ21: =E21+O21+Y21+AI21 | AR21: =F21+P21+Z21+AJ21 | AS21: =G21+Q21+AA21+AK21 | AT21: =H21+R21+AB21+AL21 | AU21: =AT21*7.45 | AV21: =I21+S21+AC21+AM21 | AW21: =K21+U21+AE21+AO21 | AX21: =L21+V21+AF21+AP21 | AY21: =IF(AW21>0, AX21/AW21, 0)
A22: 46158 | B22: Sat | C22: 0.3125 | D22: 0.58333333 | E22: =IF(B22="Sun", 0, IF(B22="Sat", 6, 12)) | F22: =IF(OR(D22="OFF", ISBLANK(D22)), 0, (D22 - C22)*24) | G22: =IF(OR(B22="Sun", D22="OFF", ISBLANK(D22)), 0, MAX(0, (IF(B22="Sat", 14/24, 20/24) - D22)*24)) | H22: 14 | I22: =H22*7.45 | J22: =IF(F22>0, I22/F22, 0) | K22: =I22 + (G22*J22) | L22: =G22*J22 | M22: 0.3125 | N22: 0.58333333 | O22: =IF(B22="Sun", 0, IF(B22="Sat", 6, 12)) | P22: =IF(OR(N22="OFF", ISBLANK(N22)), 0, (N22 - M22)*24) | Q22: =IF(OR(B22="Sun", N22="OFF", ISBLANK(N22)), 0, MAX(0, (IF(B22="Sat", 14/24, 20/24) - N22)*24)) | R22: 1 | S22: =R22*7.45 | T22: =IF(P22>0, S22/P22, 0) | U22: =S22 + (Q22*T22) | V22: =Q22*T22 | W22: 0.3125 | X22: 0.58333333 | Y22: =IF(B22="Sun", 0, IF(B22="Sat", 6, 12)) | Z22: =IF(OR(X22="OFF", ISBLANK(X22)), 0, (X22 - W22)*24) | AA22: =IF(OR(B22="Sun", X22="OFF", ISBLANK(X22)), 0, MAX(0, (IF(B22="Sat", 14/24, 20/24) - X22)*24)) | AB22: 1 | AC22: =AB22*7.45 | AD22: =IF(Z22>0, AC22/Z22, 0) | AE22: =AC22 + (AA22*AD22) | AF22: =AA22*AD22 | AG22: 0.3125 | AH22: 0.58333333 | AI22: =IF(B22="Sun", 0, IF(B22="Sat", 6, 12)) | AJ22: =IF(OR(AH22="OFF", ISBLANK(AH22)), 0, (AH22 - AG22)*24) | AK22: =IF(OR(B22="Sun", AH22="OFF", ISBLANK(AH22)), 0, MAX(0, (IF(B22="Sat", 14/24, 20/24) - AH22)*24)) | AL22: 0 | AM22: =AL22*7.45 | AN22: =IF(AJ22>0, AM22/AJ22, 0) | AO22: =AM22 + (AK22*AN22) | AP22: =AK22*AN22 | AQ22: =E22+O22+Y22+AI22 | AR22: =F22+P22+Z22+AJ22 | AS22: =G22+Q22+AA22+AK22 | AT22: =H22+R22+AB22+AL22 | AU22: =AT22*7.45 | AV22: =I22+S22+AC22+AM22 | AW22: =K22+U22+AE22+AO22 | AX22: =L22+V22+AF22+AP22 | AY22: =IF(AW22>0, AX22/AW22, 0)
A23: 46159 | B23: Sun | C23: OFF | D23: OFF | E23: =IF(B23="Sun", 0, IF(B23="Sat", 6, 12)) | F23: =IF(OR(D23="OFF", ISBLANK(D23)), 0, (D23 - C23)*24) | G23: =IF(OR(B23="Sun", D23="OFF", ISBLANK(D23)), 0, MAX(0, (IF(B23="Sat", 14/24, 20/24) - D23)*24)) | H23: 1 | I23: =H23*7.45 | J23: =IF(F23>0, I23/F23, 0) | K23: =I23 + (G23*J23) | L23: =G23*J23 | M23: OFF | N23: OFF | O23: =IF(B23="Sun", 0, IF(B23="Sat", 6, 12)) | P23: =IF(OR(N23="OFF", ISBLANK(N23)), 0, (N23 - M23)*24) | Q23: =IF(OR(B23="Sun", N23="OFF", ISBLANK(N23)), 0, MAX(0, (IF(B23="Sat", 14/24, 20/24) - N23)*24)) | R23: 1 | S23: =R23*7.45 | T23: =IF(P23>0, S23/P23, 0) | U23: =S23 + (Q23*T23) | V23: =Q23*T23 | W23: OFF | X23: OFF | Y23: =IF(B23="Sun", 0, IF(B23="Sat", 6, 12)) | Z23: =IF(OR(X23="OFF", ISBLANK(X23)), 0, (X23 - W23)*24) | AA23: =IF(OR(B23="Sun", X23="OFF", ISBLANK(X23)), 0, MAX(0, (IF(B23="Sat", 14/24, 20/24) - X23)*24)) | AB23: 0 | AC23: =AB23*7.45 | AD23: =IF(Z23>0, AC23/Z23, 0) | AE23: =AC23 + (AA23*AD23) | AF23: =AA23*AD23 | AG23: OFF | AH23: OFF | AI23: =IF(B23="Sun", 0, IF(B23="Sat", 6, 12)) | AJ23: =IF(OR(AH23="OFF", ISBLANK(AH23)), 0, (AH23 - AG23)*24) | AK23: =IF(OR(B23="Sun", AH23="OFF", ISBLANK(AH23)), 0, MAX(0, (IF(B23="Sat", 14/24, 20/24) - AH23)*24)) | AL23: 1 | AM23: =AL23*7.45 | AN23: =IF(AJ23>0, AM23/AJ23, 0) | AO23: =AM23 + (AK23*AN23) | AP23: =AK23*AN23 | AQ23: =E23+O23+Y23+AI23 | AR23: =F23+P23+Z23+AJ23 | AS23: =G23+Q23+AA23+AK23 | AT23: =H23+R23+AB23+AL23 | AU23: =AT23*7.45 | AV23: =I23+S23+AC23+AM23 | AW23: =K23+U23+AE23+AO23 | AX23: =L23+V23+AF23+AP23 | AY23: =IF(AW23>0, AX23/AW23, 0)
A24: 46160 | B24: Mon | C24: 0.29861111 | D24: 0.79861111 | E24: =IF(B24="Sun", 0, IF(B24="Sat", 6, 12)) | F24: =IF(OR(D24="OFF", ISBLANK(D24)), 0, (D24 - C24)*24) | G24: =IF(OR(B24="Sun", D24="OFF", ISBLANK(D24)), 0, MAX(0, (IF(B24="Sat", 14/24, 20/24) - D24)*24)) | H24: 69 | I24: =H24*7.45 | J24: =IF(F24>0, I24/F24, 0) | K24: =I24 + (G24*J24) | L24: =G24*J24 | M24: 0.29861111 | N24: 0.83333333 | O24: =IF(B24="Sun", 0, IF(B24="Sat", 6, 12)) | P24: =IF(OR(N24="OFF", ISBLANK(N24)), 0, (N24 - M24)*24) | Q24: =IF(OR(B24="Sun", N24="OFF", ISBLANK(N24)), 0, MAX(0, (IF(B24="Sat", 14/24, 20/24) - N24)*24)) | R24: 69 | S24: =R24*7.45 | T24: =IF(P24>0, S24/P24, 0) | U24: =S24 + (Q24*T24) | V24: =Q24*T24 | W24: 0.29861111 | X24: 0.76736111 | Y24: =IF(B24="Sun", 0, IF(B24="Sat", 6, 12)) | Z24: =IF(OR(X24="OFF", ISBLANK(X24)), 0, (X24 - W24)*24) | AA24: =IF(OR(B24="Sun", X24="OFF", ISBLANK(X24)), 0, MAX(0, (IF(B24="Sat", 14/24, 20/24) - X24)*24)) | AB24: 65 | AC24: =AB24*7.45 | AD24: =IF(Z24>0, AC24/Z24, 0) | AE24: =AC24 + (AA24*AD24) | AF24: =AA24*AD24 | AG24: 0.29861111 | AH24: 0.75763889 | AI24: =IF(B24="Sun", 0, IF(B24="Sat", 6, 12)) | AJ24: =IF(OR(AH24="OFF", ISBLANK(AH24)), 0, (AH24 - AG24)*24) | AK24: =IF(OR(B24="Sun", AH24="OFF", ISBLANK(AH24)), 0, MAX(0, (IF(B24="Sat", 14/24, 20/24) - AH24)*24)) | AL24: 64 | AM24: =AL24*7.45 | AN24: =IF(AJ24>0, AM24/AJ24, 0) | AO24: =AM24 + (AK24*AN24) | AP24: =AK24*AN24 | AQ24: =E24+O24+Y24+AI24 | AR24: =F24+P24+Z24+AJ24 | AS24: =G24+Q24+AA24+AK24 | AT24: =H24+R24+AB24+AL24 | AU24: =AT24*7.45 | AV24: =I24+S24+AC24+AM24 | AW24: =K24+U24+AE24+AO24 | AX24: =L24+V24+AF24+AP24 | AY24: =IF(AW24>0, AX24/AW24, 0)
A25: 46161 | B25: Tue | C25: 0.31597222 | D25: 0.77430556 | E25: =IF(B25="Sun", 0, IF(B25="Sat", 6, 12)) | F25: =IF(OR(D25="OFF", ISBLANK(D25)), 0, (D25 - C25)*24) | G25: =IF(OR(B25="Sun", D25="OFF", ISBLANK(D25)), 0, MAX(0, (IF(B25="Sat", 14/24, 20/24) - D25)*24)) | H25: 90 | I25: =H25*7.45 | J25: =IF(F25>0, I25/F25, 0) | K25: =I25 + (G25*J25) | L25: =G25*J25 | M25: 0.31597222 | N25: 0.80208333 | O25: =IF(B25="Sun", 0, IF(B25="Sat", 6, 12)) | P25: =IF(OR(N25="OFF", ISBLANK(N25)), 0, (N25 - M25)*24) | Q25: =IF(OR(B25="Sun", N25="OFF", ISBLANK(N25)), 0, MAX(0, (IF(B25="Sat", 14/24, 20/24) - N25)*24)) | R25: 65 | S25: =R25*7.45 | T25: =IF(P25>0, S25/P25, 0) | U25: =S25 + (Q25*T25) | V25: =Q25*T25 | W25: 0.31597222 | X25: 0.73611111 | Y25: =IF(B25="Sun", 0, IF(B25="Sat", 6, 12)) | Z25: =IF(OR(X25="OFF", ISBLANK(X25)), 0, (X25 - W25)*24) | AA25: =IF(OR(B25="Sun", X25="OFF", ISBLANK(X25)), 0, MAX(0, (IF(B25="Sat", 14/24, 20/24) - X25)*24)) | AB25: 58 | AC25: =AB25*7.45 | AD25: =IF(Z25>0, AC25/Z25, 0) | AE25: =AC25 + (AA25*AD25) | AF25: =AA25*AD25 | AG25: 0.31597222 | AH25: 0.71458333 | AI25: =IF(B25="Sun", 0, IF(B25="Sat", 6, 12)) | AJ25: =IF(OR(AH25="OFF", ISBLANK(AH25)), 0, (AH25 - AG25)*24) | AK25: =IF(OR(B25="Sun", AH25="OFF", ISBLANK(AH25)), 0, MAX(0, (IF(B25="Sat", 14/24, 20/24) - AH25)*24)) | AL25: 50 | AM25: =AL25*7.45 | AN25: =IF(AJ25>0, AM25/AJ25, 0) | AO25: =AM25 + (AK25*AN25) | AP25: =AK25*AN25 | AQ25: =E25+O25+Y25+AI25 | AR25: =F25+P25+Z25+AJ25 | AS25: =G25+Q25+AA25+AK25 | AT25: =H25+R25+AB25+AL25 | AU25: =AT25*7.45 | AV25: =I25+S25+AC25+AM25 | AW25: =K25+U25+AE25+AO25 | AX25: =L25+V25+AF25+AP25 | AY25: =IF(AW25>0, AX25/AW25, 0)
A26: 46162 | B26: Wed | C26: 0.31805556 | D26: 0.79513889 | E26: =IF(B26="Sun", 0, IF(B26="Sat", 6, 12)) | F26: =IF(OR(D26="OFF", ISBLANK(D26)), 0, (D26 - C26)*24) | G26: =IF(OR(B26="Sun", D26="OFF", ISBLANK(D26)), 0, MAX(0, (IF(B26="Sat", 14/24, 20/24) - D26)*24)) | H26: 81 | I26: =H26*7.45 | J26: =IF(F26>0, I26/F26, 0) | K26: =I26 + (G26*J26) | L26: =G26*J26 | M26: 0.31805556 | N26: 0.79513889 | O26: =IF(B26="Sun", 0, IF(B26="Sat", 6, 12)) | P26: =IF(OR(N26="OFF", ISBLANK(N26)), 0, (N26 - M26)*24) | Q26: =IF(OR(B26="Sun", N26="OFF", ISBLANK(N26)), 0, MAX(0, (IF(B26="Sat", 14/24, 20/24) - N26)*24)) | R26: 62 | S26: =R26*7.45 | T26: =IF(P26>0, S26/P26, 0) | U26: =S26 + (Q26*T26) | V26: =Q26*T26 | W26: 0.31805556 | X26: 0.76736111 | Y26: =IF(B26="Sun", 0, IF(B26="Sat", 6, 12)) | Z26: =IF(OR(X26="OFF", ISBLANK(X26)), 0, (X26 - W26)*24) | AA26: =IF(OR(B26="Sun", X26="OFF", ISBLANK(X26)), 0, MAX(0, (IF(B26="Sat", 14/24, 20/24) - X26)*24)) | AB26: 61 | AC26: =AB26*7.45 | AD26: =IF(Z26>0, AC26/Z26, 0) | AE26: =AC26 + (AA26*AD26) | AF26: =AA26*AD26 | AG26: 0.31805556 | AH26: 0.76736111 | AI26: =IF(B26="Sun", 0, IF(B26="Sat", 6, 12)) | AJ26: =IF(OR(AH26="OFF", ISBLANK(AH26)), 0, (AH26 - AG26)*24) | AK26: =IF(OR(B26="Sun", AH26="OFF", ISBLANK(AH26)), 0, MAX(0, (IF(B26="Sat", 14/24, 20/24) - AH26)*24)) | AL26: 63 | AM26: =AL26*7.45 | AN26: =IF(AJ26>0, AM26/AJ26, 0) | AO26: =AM26 + (AK26*AN26) | AP26: =AK26*AN26 | AQ26: =E26+O26+Y26+AI26 | AR26: =F26+P26+Z26+AJ26 | AS26: =G26+Q26+AA26+AK26 | AT26: =H26+R26+AB26+AL26 | AU26: =AT26*7.45 | AV26: =I26+S26+AC26+AM26 | AW26: =K26+U26+AE26+AO26 | AX26: =L26+V26+AF26+AP26 | AY26: =IF(AW26>0, AX26/AW26, 0)
A27: 46163 | B27: Thu | C27: 0.31597222 | D27: 0.78125 | E27: =IF(B27="Sun", 0, IF(B27="Sat", 6, 12)) | F27: =IF(OR(D27="OFF", ISBLANK(D27)), 0, (D27 - C27)*24) | G27: =IF(OR(B27="Sun", D27="OFF", ISBLANK(D27)), 0, MAX(0, (IF(B27="Sat", 14/24, 20/24) - D27)*24)) | H27: 81 | I27: =H27*7.45 | J27: =IF(F27>0, I27/F27, 0) | K27: =I27 + (G27*J27) | L27: =G27*J27 | M27: 0.31597222 | N27: 0.79305556 | O27: =IF(B27="Sun", 0, IF(B27="Sat", 6, 12)) | P27: =IF(OR(N27="OFF", ISBLANK(N27)), 0, (N27 - M27)*24) | Q27: =IF(OR(B27="Sun", N27="OFF", ISBLANK(N27)), 0, MAX(0, (IF(B27="Sat", 14/24, 20/24) - N27)*24)) | R27: 62 | S27: =R27*7.45 | T27: =IF(P27>0, S27/P27, 0) | U27: =S27 + (Q27*T27) | V27: =Q27*T27 | W27: 0.31597222 | X27: 0.725 | Y27: =IF(B27="Sun", 0, IF(B27="Sat", 6, 12)) | Z27: =IF(OR(X27="OFF", ISBLANK(X27)), 0, (X27 - W27)*24) | AA27: =IF(OR(B27="Sun", X27="OFF", ISBLANK(X27)), 0, MAX(0, (IF(B27="Sat", 14/24, 20/24) - X27)*24)) | AB27: 58 | AC27: =AB27*7.45 | AD27: =IF(Z27>0, AC27/Z27, 0) | AE27: =AC27 + (AA27*AD27) | AF27: =AA27*AD27 | AG27: 0.31597222 | AH27: 0.725 | AI27: =IF(B27="Sun", 0, IF(B27="Sat", 6, 12)) | AJ27: =IF(OR(AH27="OFF", ISBLANK(AH27)), 0, (AH27 - AG27)*24) | AK27: =IF(OR(B27="Sun", AH27="OFF", ISBLANK(AH27)), 0, MAX(0, (IF(B27="Sat", 14/24, 20/24) - AH27)*24)) | AL27: 59 | AM27: =AL27*7.45 | AN27: =IF(AJ27>0, AM27/AJ27, 0) | AO27: =AM27 + (AK27*AN27) | AP27: =AK27*AN27 | AQ27: =E27+O27+Y27+AI27 | AR27: =F27+P27+Z27+AJ27 | AS27: =G27+Q27+AA27+AK27 | AT27: =H27+R27+AB27+AL27 | AU27: =AT27*7.45 | AV27: =I27+S27+AC27+AM27 | AW27: =K27+U27+AE27+AO27 | AX27: =L27+V27+AF27+AP27 | AY27: =IF(AW27>0, AX27/AW27, 0)
A28: 46164 | B28: Fri | C28: 0.31597222 | D28: 0.79513889 | E28: =IF(B28="Sun", 0, IF(B28="Sat", 6, 12)) | F28: =IF(OR(D28="OFF", ISBLANK(D28)), 0, (D28 - C28)*24) | G28: =IF(OR(B28="Sun", D28="OFF", ISBLANK(D28)), 0, MAX(0, (IF(B28="Sat", 14/24, 20/24) - D28)*24)) | H28: 85 | I28: =H28*7.45 | J28: =IF(F28>0, I28/F28, 0) | K28: =I28 + (G28*J28) | L28: =G28*J28 | M28: 0.31597222 | N28: 0.79513889 | O28: =IF(B28="Sun", 0, IF(B28="Sat", 6, 12)) | P28: =IF(OR(N28="OFF", ISBLANK(N28)), 0, (N28 - M28)*24) | Q28: =IF(OR(B28="Sun", N28="OFF", ISBLANK(N28)), 0, MAX(0, (IF(B28="Sat", 14/24, 20/24) - N28)*24)) | R28: 61 | S28: =R28*7.45 | T28: =IF(P28>0, S28/P28, 0) | U28: =S28 + (Q28*T28) | V28: =Q28*T28 | W28: 0.31597222 | X28: 0.79513889 | Y28: =IF(B28="Sun", 0, IF(B28="Sat", 6, 12)) | Z28: =IF(OR(X28="OFF", ISBLANK(X28)), 0, (X28 - W28)*24) | AA28: =IF(OR(B28="Sun", X28="OFF", ISBLANK(X28)), 0, MAX(0, (IF(B28="Sat", 14/24, 20/24) - X28)*24)) | AB28: 66 | AC28: =AB28*7.45 | AD28: =IF(Z28>0, AC28/Z28, 0) | AE28: =AC28 + (AA28*AD28) | AF28: =AA28*AD28 | AG28: 0.31597222 | AH28: 0.79513889 | AI28: =IF(B28="Sun", 0, IF(B28="Sat", 6, 12)) | AJ28: =IF(OR(AH28="OFF", ISBLANK(AH28)), 0, (AH28 - AG28)*24) | AK28: =IF(OR(B28="Sun", AH28="OFF", ISBLANK(AH28)), 0, MAX(0, (IF(B28="Sat", 14/24, 20/24) - AH28)*24)) | AL28: 67 | AM28: =AL28*7.45 | AN28: =IF(AJ28>0, AM28/AJ28, 0) | AO28: =AM28 + (AK28*AN28) | AP28: =AK28*AN28 | AQ28: =E28+O28+Y28+AI28 | AR28: =F28+P28+Z28+AJ28 | AS28: =G28+Q28+AA28+AK28 | AT28: =H28+R28+AB28+AL28 | AU28: =AT28*7.45 | AV28: =I28+S28+AC28+AM28 | AW28: =K28+U28+AE28+AO28 | AX28: =L28+V28+AF28+AP28 | AY28: =IF(AW28>0, AX28/AW28, 0)
A29: 46165 | B29: Sat | C29: OFF | D29: OFF | E29: =IF(B29="Sun", 0, IF(B29="Sat", 6, 12)) | F29: =IF(OR(D29="OFF", ISBLANK(D29)), 0, (D29 - C29)*24) | G29: =IF(OR(B29="Sun", D29="OFF", ISBLANK(D29)), 0, MAX(0, (IF(B29="Sat", 14/24, 20/24) - D29)*24)) | H29: 22 | I29: =H29*7.45 | J29: =IF(F29>0, I29/F29, 0) | K29: =I29 + (G29*J29) | L29: =G29*J29 | M29: OFF | N29: OFF | O29: =IF(B29="Sun", 0, IF(B29="Sat", 6, 12)) | P29: =IF(OR(N29="OFF", ISBLANK(N29)), 0, (N29 - M29)*24) | Q29: =IF(OR(B29="Sun", N29="OFF", ISBLANK(N29)), 0, MAX(0, (IF(B29="Sat", 14/24, 20/24) - N29)*24)) | R29: 0 | S29: =R29*7.45 | T29: =IF(P29>0, S29/P29, 0) | U29: =S29 + (Q29*T29) | V29: =Q29*T29 | W29: 0.43194444 | X29: 0.58402778 | Y29: =IF(B29="Sun", 0, IF(B29="Sat", 6, 12)) | Z29: =IF(OR(X29="OFF", ISBLANK(X29)), 0, (X29 - W29)*24) | AA29: =IF(OR(B29="Sun", X29="OFF", ISBLANK(X29)), 0, MAX(0, (IF(B29="Sat", 14/24, 20/24) - X29)*24)) | AB29: 21 | AC29: =AB29*7.45 | AD29: =IF(Z29>0, AC29/Z29, 0) | AE29: =AC29 + (AA29*AD29) | AF29: =AA29*AD29 | AG29: OFF | AH29: OFF | AI29: =IF(B29="Sun", 0, IF(B29="Sat", 6, 12)) | AJ29: =IF(OR(AH29="OFF", ISBLANK(AH29)), 0, (AH29 - AG29)*24) | AK29: =IF(OR(B29="Sun", AH29="OFF", ISBLANK(AH29)), 0, MAX(0, (IF(B29="Sat", 14/24, 20/24) - AH29)*24)) | AL29: 2 | AM29: =AL29*7.45 | AN29: =IF(AJ29>0, AM29/AJ29, 0) | AO29: =AM29 + (AK29*AN29) | AP29: =AK29*AN29 | AQ29: =E29+O29+Y29+AI29 | AR29: =F29+P29+Z29+AJ29 | AS29: =G29+Q29+AA29+AK29 | AT29: =H29+R29+AB29+AL29 | AU29: =AT29*7.45 | AV29: =I29+S29+AC29+AM29 | AW29: =K29+U29+AE29+AO29 | AX29: =L29+V29+AF29+AP29 | AY29: =IF(AW29>0, AX29/AW29, 0)
A30: 46166 | B30: Sun | C30: OFF | D30: OFF | E30: =IF(B30="Sun", 0, IF(B30="Sat", 6, 12)) | F30: =IF(OR(D30="OFF", ISBLANK(D30)), 0, (D30 - C30)*24) | G30: =IF(OR(B30="Sun", D30="OFF", ISBLANK(D30)), 0, MAX(0, (IF(B30="Sat", 14/24, 20/24) - D30)*24)) | H30: 0 | I30: =H30*7.45 | J30: =IF(F30>0, I30/F30, 0) | K30: =I30 + (G30*J30) | L30: =G30*J30 | M30: OFF | N30: OFF | O30: =IF(B30="Sun", 0, IF(B30="Sat", 6, 12)) | P30: =IF(OR(N30="OFF", ISBLANK(N30)), 0, (N30 - M30)*24) | Q30: =IF(OR(B30="Sun", N30="OFF", ISBLANK(N30)), 0, MAX(0, (IF(B30="Sat", 14/24, 20/24) - N30)*24)) | R30: 0 | S30: =R30*7.45 | T30: =IF(P30>0, S30/P30, 0) | U30: =S30 + (Q30*T30) | V30: =Q30*T30 | W30: OFF | X30: OFF | Y30: =IF(B30="Sun", 0, IF(B30="Sat", 6, 12)) | Z30: =IF(OR(X30="OFF", ISBLANK(X30)), 0, (X30 - W30)*24) | AA30: =IF(OR(B30="Sun", X30="OFF", ISBLANK(X30)), 0, MAX(0, (IF(B30="Sat", 14/24, 20/24) - X30)*24)) | AB30: 0 | AC30: =AB30*7.45 | AD30: =IF(Z30>0, AC30/Z30, 0) | AE30: =AC30 + (AA30*AD30) | AF30: =AA30*AD30 | AG30: OFF | AH30: OFF | AI30: =IF(B30="Sun", 0, IF(B30="Sat", 6, 12)) | AJ30: =IF(OR(AH30="OFF", ISBLANK(AH30)), 0, (AH30 - AG30)*24) | AK30: =IF(OR(B30="Sun", AH30="OFF", ISBLANK(AH30)), 0, MAX(0, (IF(B30="Sat", 14/24, 20/24) - AH30)*24)) | AL30: 1 | AM30: =AL30*7.45 | AN30: =IF(AJ30>0, AM30/AJ30, 0) | AO30: =AM30 + (AK30*AN30) | AP30: =AK30*AN30 | AQ30: =E30+O30+Y30+AI30 | AR30: =F30+P30+Z30+AJ30 | AS30: =G30+Q30+AA30+AK30 | AT30: =H30+R30+AB30+AL30 | AU30: =AT30*7.45 | AV30: =I30+S30+AC30+AM30 | AW30: =K30+U30+AE30+AO30 | AX30: =L30+V30+AF30+AP30 | AY30: =IF(AW30>0, AX30/AW30, 0)
A31: 46167 | B31: Mon | C31: 0.3125 | D31: 0.83333333 | E31: =IF(B31="Sun", 0, IF(B31="Sat", 6, 12)) | F31: =IF(OR(D31="OFF", ISBLANK(D31)), 0, (D31 - C31)*24) | G31: =IF(OR(B31="Sun", D31="OFF", ISBLANK(D31)), 0, MAX(0, (IF(B31="Sat", 14/24, 20/24) - D31)*24)) | H31: 97 | I31: =H31*7.45 | J31: =IF(F31>0, I31/F31, 0) | K31: =I31 + (G31*J31) | L31: =G31*J31 | M31: 0.31458333 | N31: 0.83333333 | O31: =IF(B31="Sun", 0, IF(B31="Sat", 6, 12)) | P31: =IF(OR(N31="OFF", ISBLANK(N31)), 0, (N31 - M31)*24) | Q31: =IF(OR(B31="Sun", N31="OFF", ISBLANK(N31)), 0, MAX(0, (IF(B31="Sat", 14/24, 20/24) - N31)*24)) | R31: 70 | S31: =R31*7.45 | T31: =IF(P31>0, S31/P31, 0) | U31: =S31 + (Q31*T31) | V31: =Q31*T31 | W31: 0.3125 | X31: 0.80347222 | Y31: =IF(B31="Sun", 0, IF(B31="Sat", 6, 12)) | Z31: =IF(OR(X31="OFF", ISBLANK(X31)), 0, (X31 - W31)*24) | AA31: =IF(OR(B31="Sun", X31="OFF", ISBLANK(X31)), 0, MAX(0, (IF(B31="Sat", 14/24, 20/24) - X31)*24)) | AB31: 112 | AC31: =AB31*7.45 | AD31: =IF(Z31>0, AC31/Z31, 0) | AE31: =AC31 + (AA31*AD31) | AF31: =AA31*AD31 | AG31: 0.31458333 | AH31: 0.83333333 | AI31: =IF(B31="Sun", 0, IF(B31="Sat", 6, 12)) | AJ31: =IF(OR(AH31="OFF", ISBLANK(AH31)), 0, (AH31 - AG31)*24) | AK31: =IF(OR(B31="Sun", AH31="OFF", ISBLANK(AH31)), 0, MAX(0, (IF(B31="Sat", 14/24, 20/24) - AH31)*24)) | AL31: 82 | AM31: =AL31*7.45 | AN31: =IF(AJ31>0, AM31/AJ31, 0) | AO31: =AM31 + (AK31*AN31) | AP31: =AK31*AN31 | AQ31: =E31+O31+Y31+AI31 | AR31: =F31+P31+Z31+AJ31 | AS31: =G31+Q31+AA31+AK31 | AT31: =H31+R31+AB31+AL31 | AU31: =AT31*7.45 | AV31: =I31+S31+AC31+AM31 | AW31: =K31+U31+AE31+AO31 | AX31: =L31+V31+AF31+AP31 | AY31: =IF(AW31>0, AX31/AW31, 0)
A32: 46168 | B32: Tue | C32: 0.26736111 | D32: 0.79166667 | E32: =IF(B32="Sun", 0, IF(B32="Sat", 6, 12)) | F32: =IF(OR(D32="OFF", ISBLANK(D32)), 0, (D32 - C32)*24) | G32: =IF(OR(B32="Sun", D32="OFF", ISBLANK(D32)), 0, MAX(0, (IF(B32="Sat", 14/24, 20/24) - D32)*24)) | H32: 95 | I32: =H32*7.45 | J32: =IF(F32>0, I32/F32, 0) | K32: =I32 + (G32*J32) | L32: =G32*J32 | M32: 0.26736111 | N32: 0.79166667 | O32: =IF(B32="Sun", 0, IF(B32="Sat", 6, 12)) | P32: =IF(OR(N32="OFF", ISBLANK(N32)), 0, (N32 - M32)*24) | Q32: =IF(OR(B32="Sun", N32="OFF", ISBLANK(N32)), 0, MAX(0, (IF(B32="Sat", 14/24, 20/24) - N32)*24)) | R32: 75 | S32: =R32*7.45 | T32: =IF(P32>0, S32/P32, 0) | U32: =S32 + (Q32*T32) | V32: =Q32*T32 | W32: 0.26736111 | X32: 0.78125 | Y32: =IF(B32="Sun", 0, IF(B32="Sat", 6, 12)) | Z32: =IF(OR(X32="OFF", ISBLANK(X32)), 0, (X32 - W32)*24) | AA32: =IF(OR(B32="Sun", X32="OFF", ISBLANK(X32)), 0, MAX(0, (IF(B32="Sat", 14/24, 20/24) - X32)*24)) | AB32: 96 | AC32: =AB32*7.45 | AD32: =IF(Z32>0, AC32/Z32, 0) | AE32: =AC32 + (AA32*AD32) | AF32: =AA32*AD32 | AG32: 0.26736111 | AH32: 0.78125 | AI32: =IF(B32="Sun", 0, IF(B32="Sat", 6, 12)) | AJ32: =IF(OR(AH32="OFF", ISBLANK(AH32)), 0, (AH32 - AG32)*24) | AK32: =IF(OR(B32="Sun", AH32="OFF", ISBLANK(AH32)), 0, MAX(0, (IF(B32="Sat", 14/24, 20/24) - AH32)*24)) | AL32: 89 | AM32: =AL32*7.45 | AN32: =IF(AJ32>0, AM32/AJ32, 0) | AO32: =AM32 + (AK32*AN32) | AP32: =AK32*AN32 | AQ32: =E32+O32+Y32+AI32 | AR32: =F32+P32+Z32+AJ32 | AS32: =G32+Q32+AA32+AK32 | AT32: =H32+R32+AB32+AL32 | AU32: =AT32*7.45 | AV32: =I32+S32+AC32+AM32 | AW32: =K32+U32+AE32+AO32 | AX32: =L32+V32+AF32+AP32 | AY32: =IF(AW32>0, AX32/AW32, 0)
A33: 46169 | B33: Wed | C33: OFF | D33: OFF | E33: =IF(B33="Sun", 0, IF(B33="Sat", 6, 12)) | F33: =IF(OR(D33="OFF", ISBLANK(D33)), 0, (D33 - C33)*24) | G33: =IF(OR(B33="Sun", D33="OFF", ISBLANK(D33)), 0, MAX(0, (IF(B33="Sat", 14/24, 20/24) - D33)*24)) | H33: 1 | I33: =H33*7.45 | J33: =IF(F33>0, I33/F33, 0) | K33: =I33 + (G33*J33) | L33: =G33*J33 | M33: OFF | N33: OFF | O33: =IF(B33="Sun", 0, IF(B33="Sat", 6, 12)) | P33: =IF(OR(N33="OFF", ISBLANK(N33)), 0, (N33 - M33)*24) | Q33: =IF(OR(B33="Sun", N33="OFF", ISBLANK(N33)), 0, MAX(0, (IF(B33="Sat", 14/24, 20/24) - N33)*24)) | R33: 1 | S33: =R33*7.45 | T33: =IF(P33>0, S33/P33, 0) | U33: =S33 + (Q33*T33) | V33: =Q33*T33 | W33: OFF | X33: OFF | Y33: =IF(B33="Sun", 0, IF(B33="Sat", 6, 12)) | Z33: =IF(OR(X33="OFF", ISBLANK(X33)), 0, (X33 - W33)*24) | AA33: =IF(OR(B33="Sun", X33="OFF", ISBLANK(X33)), 0, MAX(0, (IF(B33="Sat", 14/24, 20/24) - X33)*24)) | AB33: 4 | AC33: =AB33*7.45 | AD33: =IF(Z33>0, AC33/Z33, 0) | AE33: =AC33 + (AA33*AD33) | AF33: =AA33*AD33 | AG33: OFF | AH33: OFF | AI33: =IF(B33="Sun", 0, IF(B33="Sat", 6, 12)) | AJ33: =IF(OR(AH33="OFF", ISBLANK(AH33)), 0, (AH33 - AG33)*24) | AK33: =IF(OR(B33="Sun", AH33="OFF", ISBLANK(AH33)), 0, MAX(0, (IF(B33="Sat", 14/24, 20/24) - AH33)*24)) | AL33: 4 | AM33: =AL33*7.45 | AN33: =IF(AJ33>0, AM33/AJ33, 0) | AO33: =AM33 + (AK33*AN33) | AP33: =AK33*AN33 | AQ33: =E33+O33+Y33+AI33 | AR33: =F33+P33+Z33+AJ33 | AS33: =G33+Q33+AA33+AK33 | AT33: =H33+R33+AB33+AL33 | AU33: =AT33*7.45 | AV33: =I33+S33+AC33+AM33 | AW33: =K33+U33+AE33+AO33 | AX33: =L33+V33+AF33+AP33 | AY33: =IF(AW33>0, AX33/AW33, 0)
A34: 46170 | B34: Thu | C34: 0.28819444 | D34: 0.78194444 | E34: =IF(B34="Sun", 0, IF(B34="Sat", 6, 12)) | F34: =IF(OR(D34="OFF", ISBLANK(D34)), 0, (D34 - C34)*24) | G34: =IF(OR(B34="Sun", D34="OFF", ISBLANK(D34)), 0, MAX(0, (IF(B34="Sat", 14/24, 20/24) - D34)*24)) | H34: 81 | I34: =H34*7.45 | J34: =IF(F34>0, I34/F34, 0) | K34: =I34 + (G34*J34) | L34: =G34*J34 | M34: 0.28819444 | N34: 0.78194444 | O34: =IF(B34="Sun", 0, IF(B34="Sat", 6, 12)) | P34: =IF(OR(N34="OFF", ISBLANK(N34)), 0, (N34 - M34)*24) | Q34: =IF(OR(B34="Sun", N34="OFF", ISBLANK(N34)), 0, MAX(0, (IF(B34="Sat", 14/24, 20/24) - N34)*24)) | R34: 72 | S34: =R34*7.45 | T34: =IF(P34>0, S34/P34, 0) | U34: =S34 + (Q34*T34) | V34: =Q34*T34 | W34: 0.28819444 | X34: 0.76527778 | Y34: =IF(B34="Sun", 0, IF(B34="Sat", 6, 12)) | Z34: =IF(OR(X34="OFF", ISBLANK(X34)), 0, (X34 - W34)*24) | AA34: =IF(OR(B34="Sun", X34="OFF", ISBLANK(X34)), 0, MAX(0, (IF(B34="Sat", 14/24, 20/24) - X34)*24)) | AB34: 87 | AC34: =AB34*7.45 | AD34: =IF(Z34>0, AC34/Z34, 0) | AE34: =AC34 + (AA34*AD34) | AF34: =AA34*AD34 | AG34: 0.28819444 | AH34: 0.76527778 | AI34: =IF(B34="Sun", 0, IF(B34="Sat", 6, 12)) | AJ34: =IF(OR(AH34="OFF", ISBLANK(AH34)), 0, (AH34 - AG34)*24) | AK34: =IF(OR(B34="Sun", AH34="OFF", ISBLANK(AH34)), 0, MAX(0, (IF(B34="Sat", 14/24, 20/24) - AH34)*24)) | AL34: 82 | AM34: =AL34*7.45 | AN34: =IF(AJ34>0, AM34/AJ34, 0) | AO34: =AM34 + (AK34*AN34) | AP34: =AK34*AN34 | AQ34: =E34+O34+Y34+AI34 | AR34: =F34+P34+Z34+AJ34 | AS34: =G34+Q34+AA34+AK34 | AT34: =H34+R34+AB34+AL34 | AU34: =AT34*7.45 | AV34: =I34+S34+AC34+AM34 | AW34: =K34+U34+AE34+AO34 | AX34: =L34+V34+AF34+AP34 | AY34: =IF(AW34>0, AX34/AW34, 0)
A35: 46171 | B35: Fri | C35: 0.30902778 | D35: 0.75 | E35: =IF(B35="Sun", 0, IF(B35="Sat", 6, 12)) | F35: =IF(OR(D35="OFF", ISBLANK(D35)), 0, (D35 - C35)*24) | G35: =IF(OR(B35="Sun", D35="OFF", ISBLANK(D35)), 0, MAX(0, (IF(B35="Sat", 14/24, 20/24) - D35)*24)) | H35: 75 | I35: =H35*7.45 | J35: =IF(F35>0, I35/F35, 0) | K35: =I35 + (G35*J35) | L35: =G35*J35 | M35: 0.30902778 | N35: 0.75 | O35: =IF(B35="Sun", 0, IF(B35="Sat", 6, 12)) | P35: =IF(OR(N35="OFF", ISBLANK(N35)), 0, (N35 - M35)*24) | Q35: =IF(OR(B35="Sun", N35="OFF", ISBLANK(N35)), 0, MAX(0, (IF(B35="Sat", 14/24, 20/24) - N35)*24)) | R35: 66 | S35: =R35*7.45 | T35: =IF(P35>0, S35/P35, 0) | U35: =S35 + (Q35*T35) | V35: =Q35*T35 | W35: 0.30902778 | X35: 0.75 | Y35: =IF(B35="Sun", 0, IF(B35="Sat", 6, 12)) | Z35: =IF(OR(X35="OFF", ISBLANK(X35)), 0, (X35 - W35)*24) | AA35: =IF(OR(B35="Sun", X35="OFF", ISBLANK(X35)), 0, MAX(0, (IF(B35="Sat", 14/24, 20/24) - X35)*24)) | AB35: 83 | AC35: =AB35*7.45 | AD35: =IF(Z35>0, AC35/Z35, 0) | AE35: =AC35 + (AA35*AD35) | AF35: =AA35*AD35 | AG35: 0.30902778 | AH35: 0.75 | AI35: =IF(B35="Sun", 0, IF(B35="Sat", 6, 12)) | AJ35: =IF(OR(AH35="OFF", ISBLANK(AH35)), 0, (AH35 - AG35)*24) | AK35: =IF(OR(B35="Sun", AH35="OFF", ISBLANK(AH35)), 0, MAX(0, (IF(B35="Sat", 14/24, 20/24) - AH35)*24)) | AL35: 69 | AM35: =AL35*7.45 | AN35: =IF(AJ35>0, AM35/AJ35, 0) | AO35: =AM35 + (AK35*AN35) | AP35: =AK35*AN35 | AQ35: =E35+O35+Y35+AI35 | AR35: =F35+P35+Z35+AJ35 | AS35: =G35+Q35+AA35+AK35 | AT35: =H35+R35+AB35+AL35 | AU35: =AT35*7.45 | AV35: =I35+S35+AC35+AM35 | AW35: =K35+U35+AE35+AO35 | AX35: =L35+V35+AF35+AP35 | AY35: =IF(AW35>0, AX35/AW35, 0)
A36: 46172 | B36: Sat | C36: OFF | D36: OFF | E36: =IF(B36="Sun", 0, IF(B36="Sat", 6, 12)) | F36: =IF(OR(D36="OFF", ISBLANK(D36)), 0, (D36 - C36)*24) | G36: =IF(OR(B36="Sun", D36="OFF", ISBLANK(D36)), 0, MAX(0, (IF(B36="Sat", 14/24, 20/24) - D36)*24)) | H36: 3 | I36: =H36*7.45 | J36: =IF(F36>0, I36/F36, 0) | K36: =I36 + (G36*J36) | L36: =G36*J36 | M36: 0.41388889 | N36: 0.58333333 | O36: =IF(B36="Sun", 0, IF(B36="Sat", 6, 12)) | P36: =IF(OR(N36="OFF", ISBLANK(N36)), 0, (N36 - M36)*24) | Q36: =IF(OR(B36="Sun", N36="OFF", ISBLANK(N36)), 0, MAX(0, (IF(B36="Sat", 14/24, 20/24) - N36)*24)) | R36: 37 | S36: =R36*7.45 | T36: =IF(P36>0, S36/P36, 0) | U36: =S36 + (Q36*T36) | V36: =Q36*T36 | W36: 0.30902778 | X36: 0.58333333 | Y36: =IF(B36="Sun", 0, IF(B36="Sat", 6, 12)) | Z36: =IF(OR(X36="OFF", ISBLANK(X36)), 0, (X36 - W36)*24) | AA36: =IF(OR(B36="Sun", X36="OFF", ISBLANK(X36)), 0, MAX(0, (IF(B36="Sat", 14/24, 20/24) - X36)*24)) | AB36: 72 | AC36: =AB36*7.45 | AD36: =IF(Z36>0, AC36/Z36, 0) | AE36: =AC36 + (AA36*AD36) | AF36: =AA36*AD36 | AG36: OFF | AH36: OFF | AI36: =IF(B36="Sun", 0, IF(B36="Sat", 6, 12)) | AJ36: =IF(OR(AH36="OFF", ISBLANK(AH36)), 0, (AH36 - AG36)*24) | AK36: =IF(OR(B36="Sun", AH36="OFF", ISBLANK(AH36)), 0, MAX(0, (IF(B36="Sat", 14/24, 20/24) - AH36)*24)) | AL36: 4 | AM36: =AL36*7.45 | AN36: =IF(AJ36>0, AM36/AJ36, 0) | AO36: =AM36 + (AK36*AN36) | AP36: =AK36*AN36 | AQ36: =E36+O36+Y36+AI36 | AR36: =F36+P36+Z36+AJ36 | AS36: =G36+Q36+AA36+AK36 | AT36: =H36+R36+AB36+AL36 | AU36: =AT36*7.45 | AV36: =I36+S36+AC36+AM36 | AW36: =K36+U36+AE36+AO36 | AX36: =L36+V36+AF36+AP36 | AY36: =IF(AW36>0, AX36/AW36, 0)
A37: 46173 | B37: Sun | C37: OFF | D37: OFF | E37: =IF(B37="Sun", 0, IF(B37="Sat", 6, 12)) | F37: =IF(OR(D37="OFF", ISBLANK(D37)), 0, (D37 - C37)*24) | G37: =IF(OR(B37="Sun", D37="OFF", ISBLANK(D37)), 0, MAX(0, (IF(B37="Sat", 14/24, 20/24) - D37)*24)) | H37: 1 | I37: =H37*7.45 | J37: =IF(F37>0, I37/F37, 0) | K37: =I37 + (G37*J37) | L37: =G37*J37 | M37: OFF | N37: OFF | O37: =IF(B37="Sun", 0, IF(B37="Sat", 6, 12)) | P37: =IF(OR(N37="OFF", ISBLANK(N37)), 0, (N37 - M37)*24) | Q37: =IF(OR(B37="Sun", N37="OFF", ISBLANK(N37)), 0, MAX(0, (IF(B37="Sat", 14/24, 20/24) - N37)*24)) | R37: 0 | S37: =R37*7.45 | T37: =IF(P37>0, S37/P37, 0) | U37: =S37 + (Q37*T37) | V37: =Q37*T37 | W37: OFF | X37: OFF | Y37: =IF(B37="Sun", 0, IF(B37="Sat", 6, 12)) | Z37: =IF(OR(X37="OFF", ISBLANK(X37)), 0, (X37 - W37)*24) | AA37: =IF(OR(B37="Sun", X37="OFF", ISBLANK(X37)), 0, MAX(0, (IF(B37="Sat", 14/24, 20/24) - X37)*24)) | AB37: 0 | AC37: =AB37*7.45 | AD37: =IF(Z37>0, AC37/Z37, 0) | AE37: =AC37 + (AA37*AD37) | AF37: =AA37*AD37 | AG37: OFF | AH37: OFF | AI37: =IF(B37="Sun", 0, IF(B37="Sat", 6, 12)) | AJ37: =IF(OR(AH37="OFF", ISBLANK(AH37)), 0, (AH37 - AG37)*24) | AK37: =IF(OR(B37="Sun", AH37="OFF", ISBLANK(AH37)), 0, MAX(0, (IF(B37="Sat", 14/24, 20/24) - AH37)*24)) | AL37: 1 | AM37: =AL37*7.45 | AN37: =IF(AJ37>0, AM37/AJ37, 0) | AO37: =AM37 + (AK37*AN37) | AP37: =AK37*AN37 | AQ37: =E37+O37+Y37+AI37 | AR37: =F37+P37+Z37+AJ37 | AS37: =G37+Q37+AA37+AK37 | AT37: =H37+R37+AB37+AL37 | AU37: =AT37*7.45 | AV37: =I37+S37+AC37+AM37 | AW37: =K37+U37+AE37+AO37 | AX37: =L37+V37+AF37+AP37 | AY37: =IF(AW37>0, AX37/AW37, 0)
A38: MONTH TOTAL | E38: =SUM(E7:E37) | F38: =SUM(F7:F37) | G38: =SUM(G7:G37) | H38: =SUM(H7:H37) | I38: =SUM(I7:I37) | J38: =AVERAGE(J7:J37) | K38: =SUM(K7:K37) | L38: =SUM(L7:L37) | O38: =SUM(O7:O37) | P38: =SUM(P7:P37) | Q38: =SUM(Q7:Q37) | R38: =SUM(R7:R37) | S38: =SUM(S7:S37) | T38: =AVERAGE(T7:T37) | U38: =SUM(U7:U37) | V38: =SUM(V7:V37) | Y38: =SUM(Y7:Y37) | Z38: =SUM(Z7:Z37) | AA38: =SUM(AA7:AA37) | AB38: =SUM(AB7:AB37) | AC38: =SUM(AC7:AC37) | AD38: =AVERAGE(AD7:AD37) | AE38: =SUM(AE7:AE37) | AF38: =SUM(AF7:AF37) | AI38: =SUM(AI7:AI37) | AJ38: =SUM(AJ7:AJ37) | AK38: =SUM(AK7:AK37) | AL38: =SUM(AL7:AL37) | AM38: =SUM(AM7:AM37) | AN38: =AVERAGE(AN7:AN37) | AO38: =SUM(AO7:AO37) | AP38: =SUM(AP7:AP37) | AQ38: =SUM(AQ7:AQ37) | AR38: =SUM(AR7:AR37) | AS38: =SUM(AS7:AS37) | AT38: =SUM(AT7:AT37) | AU38: =SUM(AU7:AU37) | AV38: =SUM(AV7:AV37) | ... AX38: =SUM(AX7:AX37) | AY38: =AVERAGE(AY7:AY37)

Sheet June 2026
A1: AHU DAILY SAVINGS & KWH COST REPORT - JUNE 2026
A2: Operating Schedule: Mon-Fri 8:00 AM to 8:00 PM (12 hrs/AHU) | Sat 8:00 AM to 2:00 PM (6 hrs/AHU) | Sun Off
A3: Logic: KWH Rate = Rs. 7.45 | Hourly Rate = KWH Cost / Actual Run Hrs | Full Cost = KWH Cost + (Saved Hrs * Hourly Rate) | Saving = Saved Hrs * Hourly Rate
A5: Date & Day | C5: AHU-1 (CFM 26500) | M5: AHU-2 (CFM 26700) | W5: AHU-3 (CFM 28000) | AG5: AHU-4 (CFM 28500) | AQ5: DAILY TOTAL COMBINED SUMMARY (ALL AHUs)
A6: Date | B6: Day | C6: ON Time | D6: OFF Time | E6: Sched Hrs | F6: Actual Run Hrs | G6: Saved Hrs | H6: Consumption (KWH) | I6: Actual Cost (Rs) | J6: Cost / Hr (Rs) | K6: Full Cost 8PM (Rs) | L6: Cost Saved (Rs) | M6: ON Time | N6: OFF Time | O6: Sched Hrs | P6: Actual Run Hrs | Q6: Saved Hrs | R6: Consumption (KWH) | S6: Actual Cost (Rs) | T6: Cost / Hr (Rs) | U6: Full Cost 8PM (Rs) | V6: Cost Saved (Rs) | W6: ON Time | X6: OFF Time | Y6: Sched Hrs | Z6: Actual Run Hrs | AA6: Saved Hrs | AB6: Consumption (KWH) | AC6: Actual Cost (Rs) | AD6: Cost / Hr (Rs) | AE6: Full Cost 8PM (Rs) | AF6: Cost Saved (Rs) | AG6: ON Time | AH6: OFF Time | AI6: Sched Hrs | AJ6: Actual Run Hrs | AK6: Saved Hrs | AL6: Consumption (KWH) | AM6: Actual Cost (Rs) | AN6: Cost / Hr (Rs) | AO6: Full Cost 8PM (Rs) | AP6: Cost Saved (Rs) | AQ6: Tot Sched Hrs | AR6: Tot Actual Run Hrs | AS6: Tot Saved Hrs | AT6: Tot Consumption (KWH) | AU6: KWH Cost (Rs) | AV6: Tot Actual Cost (Rs) | AW6: Tot Full Cost 8PM (Rs) | AX6: Total Cost Saved (Rs) | AY6: Savings %
A7: 46174 | B7: Mon | C7: 0.29166667 | D7: 0.79166667 | E7: =IF(B7="Sun", 0, IF(B7="Sat", 6, 12)) | F7: =IF(OR(D7="OFF", ISBLANK(D7)), 0, (D7 - C7)*24) | G7: =IF(OR(B7="Sun", D7="OFF", ISBLANK(D7)), 0, MAX(0, (IF(B7="Sat", 14/24, 20/24) - D7)*24)) | H7: 98 | I7: =H7*7.45 | J7: =IF(F7>0, I7/F7, 0) | K7: =I7 + (G7*J7) | L7: =G7*J7 | M7: 0.29166667 | N7: 0.83194444 | O7: =IF(B7="Sun", 0, IF(B7="Sat", 6, 12)) | P7: =IF(OR(N7="OFF", ISBLANK(N7)), 0, (N7 - M7)*24) | Q7: =IF(OR(B7="Sun", N7="OFF", ISBLANK(N7)), 0, MAX(0, (IF(B7="Sat", 14/24, 20/24) - N7)*24)) | R7: 81 | S7: =R7*7.45 | T7: =IF(P7>0, S7/P7, 0) | U7: =S7 + (Q7*T7) | V7: =Q7*T7 | W7: 0.29166667 | X7: 0.79027778 | Y7: =IF(B7="Sun", 0, IF(B7="Sat", 6, 12)) | Z7: =IF(OR(X7="OFF", ISBLANK(X7)), 0, (X7 - W7)*24) | AA7: =IF(OR(B7="Sun", X7="OFF", ISBLANK(X7)), 0, MAX(0, (IF(B7="Sat", 14/24, 20/24) - X7)*24)) | AB7: 98 | AC7: =AB7*7.45 | AD7: =IF(Z7>0, AC7/Z7, 0) | AE7: =AC7 + (AA7*AD7) | AF7: =AA7*AD7 | AG7: 0.29166667 | AH7: 0.79027778 | AI7: =IF(B7="Sun", 0, IF(B7="Sat", 6, 12)) | AJ7: =IF(OR(AH7="OFF", ISBLANK(AH7)), 0, (AH7 - AG7)*24) | AK7: =IF(OR(B7="Sun", AH7="OFF", ISBLANK(AH7)), 0, MAX(0, (IF(B7="Sat", 14/24, 20/24) - AH7)*24)) | AL7: 78 | AM7: =AL7*7.45 | AN7: =IF(AJ7>0, AM7/AJ7, 0) | AO7: =AM7 + (AK7*AN7) | AP7: =AK7*AN7 | AQ7: =E7+O7+Y7+AI7 | AR7: =F7+P7+Z7+AJ7 | AS7: =G7+Q7+AA7+AK7 | AT7: =H7+R7+AB7+AL7 | AU7: =AT7*7.45 | AV7: =I7+S7+AC7+AM7 | AW7: =K7+U7+AE7+AO7 | AX7: =L7+V7+AF7+AP7 | AY7: =IF(AW7>0, AX7/AW7, 0)
